Workbook

Sheet Leaderboard
A1: 🔥 LATEST RESULTS | D1: Date | E1: ='42126'!B1 -> #REF! | H1: Update Live Results | I1: FALSE
A2: =IF(AND(MAX(B5:B8)=0,COUNTIF(C5:C8,"<>0/5")=0),"",IF(COUNTIF(C5:C8,"5/5")=4,"Winner","Leader")) -> #REF! | C2: {=IF(AND(MAX(B5:B8)=0,COUNTIF(C5:C8,"<>0/5")=0),"",INDEX(A5:A8,MATCH(MAX(B5:B8),B5:B8,0)))} -> #REF! | H2: Last Refresh | I2: 46133.255
H3: Status | I3: Skipped refresh — latest tab already final: 42026
A4: Player | B4: Score | C4: Completed Games | D4: In Progress
A5: Andy | B5: ='42126'!I11 -> #REF! | C5: ='42126'!L2 -> #REF! | D5: ='41426'!M2 -> 0/5
A6: Josh | B6: ='42126'!I38 -> #REF! | C6: ='42126'!L3 -> #REF! | D6: ='41426'!M3 -> 0/5
A7: Jon | B7: ='42126'!I20 -> #REF! | C7: ='42126'!L4 -> #REF! | D7: ='41426'!M4 -> 0/5
A8: Mark | B8: ='42126'!I29 -> #REF! | C8: ='42126'!L5 -> #REF! | D8: ='41426'!M5 -> 0/5 | H8: =IFERROR(__xludf.DUMMYFUNCTION("MAX(FILTER(ROW('2026 Standings'!B:B),ROW('2026 Standings'!B:B)<MATCH(""Finishing Position"",'2026 Standings'!A:A,0),'2026 Standings'!B:B<>""""))"),13.0) -> 13
A10: Season Standings
A11: Name | B11: Wins | C11: Runner-ups | D11: Avg Finish
A12: {=SORT('2026 Standings'!A2:D5,'2026 Standings'!B2:B5,FALSE,'2026 Standings'!D2:D5,TRUE,'2026 Standings'!A2:A5,TRUE)} -> Josh | B12: 2 | C12: 2 | D12: 1.8
A13: Mark | B13: 2 | C13: 2 | D13: 1.8
A14: Jon | B14: 1 | C14: 0 | D14: 3
A15: Andy | B15: 0 | C15: 1 | D15: 3
A17: Season Leader
A18: Name | B18: Wins
A19: =INDEX(A12:A15,1) -> Josh | B19: =INDEX(B12:B15,1) -> 2

Sheet 2026 Standings
A1: Name | B1: Wins | C1: Runner-ups | D1: Avg Finish | E1: Avg Score | F1: High Score | G1: Low Score | H1: Refresh Standings | I1: FALSE
A2: Andy | B2: =COUNTIF(B18:B22,1) -> 0 | C2: =COUNTIF(B18:B22,2) -> 1 | D2: =IFERROR(AVERAGE(B18:B22),"") -> 3 | E2: =IFERROR(AVERAGE(B9:B13),"") -> 161.96 | F2: =IFERROR(MAX(B9:B13),"") -> 182.2 | G2: =IFERROR(MIN(B9:B13),"") -> 129.4 | H2: Last Refresh | I2: 46133.255
A3: Josh | B3: =COUNTIF(C18:C22,1) -> 2 | C3: =COUNTIF(C18:C22,2) -> 2 | D3: =IFERROR(AVERAGE(C18:C22),"") -> 1.8 | E3: =IFERROR(AVERAGE(C9:C13),"") -> 170.46 | F3: =IFERROR(MAX(C9:C13),"") -> 189.2 | G3: =IFERROR(MIN(C9:C13),"") -> 152.9 | H3: Status | I3: Standings refreshed
A4: Jon | B4: =COUNTIF(D18:D22,1) -> 1 | C4: =COUNTIF(D18:D22,2) -> 0 | D4: =IFERROR(AVERAGE(D18:D22),"") -> 3 | E4: =IFERROR(AVERAGE(D9:D13),"") -> 141.83333 | F4: =IFERROR(MAX(D9:D13),"") -> 200.5 | G4: =IFERROR(MIN(D9:D13),"") -> 84.5
A5: Mark | B5: =COUNTIF(E18:E22,1) -> 2 | C5: =COUNTIF(E18:E22,2) -> 2 | D5: =IFERROR(AVERAGE(E18:E22),"") -> 1.8 | E5: =IFERROR(AVERAGE(E9:E13),"") -> 185.7 | F5: =IFERROR(MAX(E9:E13),"") -> 217.9 | G5: =IFERROR(MIN(E9:E13),"") -> 138.2
A7: Scores
A8: Date | B8: Andy | C8: Josh | D8: Jon | E8: Mark
A9: 4/14/26 - 4/15/26 | B9: =IF(COUNTIF('41426'!L2:L5,"<>0/5")=0,"",IF(COUNTA('41426'!B6:B10)=0,"",'41426'!I11)) -> 182.2 | C9: =IF(COUNTIF('41426'!L2:L5,"<>0/5")=0,"",IF(COUNTA('41426'!B33:B37)=0,"",'41426'!I38)) -> 152.9 | D9: =IF(COUNTIF('41426'!L2:L5,"<>0/5")=0,"",IF(COUNTA('41426'!B15:B19)=0,"",'41426'!I20)) -> 140.5 | E9: =IF(COUNTIF('41426'!L2:L5,"<>0/5")=0,"",IF(COUNTA('41426'!B24:B28)=0,"",'41426'!I29)) -> 217.9
A10: 46129 | B10: =IF(COUNTIF('41726'!L2:L5,"<>0/5")=0,"",IF(COUNTA('41726'!B6:B10)=0,"",'41726'!I11)) -> 129.4 | C10: =IF(COUNTIF('41726'!L2:L5,"<>0/5")=0,"",IF(COUNTA('41726'!B33:B37)=0,"",'41726'!I38)) -> 153.3 | D10: =IF(COUNTIF('41726'!L2:L5,"<>0/5")=0,"",IF(COUNTA('41726'!B15:B19)=0,"",'41726'!I20)) -> 84.5 | E10: =IF(COUNTIF('41726'!L2:L5,"<>0/5")=0,"",IF(COUNTA('41726'!B24:B28)=0,"",'41726'!I29)) -> 138.2
A11: 46130 | B11: =IF(COUNTIF('41826'!L2:L5,"<>0/5")=0,"",IF(COUNTA('41826'!B6:B10)=0,"",'41826'!I11)) -> 166.9 | C11: =IF(COUNTIF('41826'!L2:L5,"<>0/5")=0,"",IF(COUNTA('41826'!B33:B37)=0,"",'41826'!I38)) -> 182.6 | D11: =IF(COUNTIF('41826'!L2:L5,"<>0/5")=0,"",IF(COUNTA('41826'!B15:B19)=0,"",'41826'!I20)) -> 200.5 | E11: =IF(COUNTIF('41826'!L2:L5,"<>0/5")=0,"",IF(COUNTA('41826'!B24:B28)=0,"",'41826'!I29)) -> 178.6
A12: 46131 | B12: =IF(COUNTIF('41926'!L2:L5,"<>0/5")=0,"",IF(COUNTA('41926'!B6:B10)=0,"",'41926'!I11)) -> 157.8 | C12: =IF(COUNTIF('41926'!L2:L5,"<>0/5")=0,"",IF(COUNTA('41926'!B33:B37)=0,"",'41926'!I38)) -> 174.3 | D12: =IF(COUNTIF('41926'!L2:L5,"<>0/5")=0,"",IF(COUNTA('41926'!B15:B19)=0,"",'41926'!I20)) | E12: =IF(COUNTIF('41926'!L2:L5,"<>0/5")=0,"",IF(COUNTA('41926'!B24:B28)=0,"",'41926'!I29)) -> 213.8
A13: 46132 | B13: =IF(COUNTIF('42026'!L2:L5,"<>0/5")=0,"",IF(COUNTA('42026'!B6:B10)=0,"",'42026'!I11)) -> 173.5 | C13: =IF(COUNTIF('42026'!L2:L5,"<>0/5")=0,"",IF(COUNTA('42026'!B33:B37)=0,"",'42026'!I38)) -> 189.2 | D13: =IF(COUNTIF('42026'!L2:L5,"<>0/5")=0,"",IF(COUNTA('42026'!B15:B19)=0,"",'42026'!I20)) | E13: =IF(COUNTIF('42026'!L2:L5,"<>0/5")=0,"",IF(COUNTA('42026'!B24:B28)=0,"",'42026'!I29)) -> 180
A16: Finishing Position
A17: Date | B17: Andy | C17: Josh | D17: Jon | E17: Mark
A18: 4/14/26 - 4/15/26 | B18: =IFERROR(__xludf.DUMMYFUNCTION("IF(B9="""","""",RANK(B9,FILTER($B9:$E9,$B9:$E9<>""""),0))"),2.0) -> 2 | C18: =IFERROR(__xludf.DUMMYFUNCTION("IF(C9="""","""",RANK(C9,FILTER($B9:$E9,$B9:$E9<>""""),0))"),3.0) -> 3 | D18: =IFERROR(__xludf.DUMMYFUNCTION("IF(D9="""","""",RANK(D9,FILTER($B9:$E9,$B9:$E9<>""""),0))"),4.0) -> 4 | E18: =IFERROR(__xludf.DUMMYFUNCTION("IF(E9="""","""",RANK(E9,FILTER($B9:$E9,$B9:$E9<>""""),0))"),1.0) -> 1
A19: 46129 | B19: =IFERROR(__xludf.DUMMYFUNCTION("IF(B10="""","""",RANK(B10,FILTER($B10:$E10,$B10:$E10<>""""),0))"),3.0) -> 3 | C19: =IFERROR(__xludf.DUMMYFUNCTION("IF(C10="""","""",RANK(C10,FILTER($B10:$E10,$B10:$E10<>""""),0))"),1.0) -> 1 | D19: =IFERROR(__xludf.DUMMYFUNCTION("IF(D10="""","""",RANK(D10,FILTER($B10:$E10,$B10:$E10<>""""),0))"),4.0) -> 4 | E19: =IFERROR(__xludf.DUMMYFUNCTION("IF(E10="""","""",RANK(E10,FILTER($B10:$E10,$B10:$E10<>""""),0))"),2.0) -> 2
A20: 46130 | B20: =IFERROR(__xludf.DUMMYFUNCTION("IF(B11="""","""",RANK(B11,FILTER($B11:$E11,$B11:$E11<>""""),0))"),4.0) -> 4 | C20: =IFERROR(__xludf.DUMMYFUNCTION("IF(C11="""","""",RANK(C11,FILTER($B11:$E11,$B11:$E11<>""""),0))"),2.0) -> 2 | D20: =IFERROR(__xludf.DUMMYFUNCTION("IF(D11="""","""",RANK(D11,FILTER($B11:$E11,$B11:$E11<>""""),0))"),1.0) -> 1 | E20: =IFERROR(__xludf.DUMMYFUNCTION("IF(E11="""","""",RANK(E11,FILTER($B11:$E11,$B11:$E11<>""""),0))"),3.0) -> 3
A21: 46131 | B21: =IFERROR(__xludf.DUMMYFUNCTION("IF(B12="""","""",RANK(B12,FILTER($B12:$E12,$B12:$E12<>""""),0))"),3.0) -> 3 | C21: =IFERROR(__xludf.DUMMYFUNCTION("IF(C12="""","""",RANK(C12,FILTER($B12:$E12,$B12:$E12<>""""),0))"),2.0) -> 2 | D21: =IFERROR(__xludf.DUMMYFUNCTION("IF(D12="""","""",RANK(D12,FILTER($B12:$E12,$B12:$E12<>""""),0))"),"") | E21: =IFERROR(__xludf.DUMMYFUNCTION("IF(E12="""","""",RANK(E12,FILTER($B12:$E12,$B12:$E12<>""""),0))"),1.0) -> 1
A22: 46132 | B22: =IFERROR(__xludf.DUMMYFUNCTION("IF(B13="""","""",RANK(B13,FILTER($B13:$E13,$B13:$E13<>""""),0))"),3.0) -> 3 | C22: =IFERROR(__xludf.DUMMYFUNCTION("IF(C13="""","""",RANK(C13,FILTER($B13:$E13,$B13:$E13<>""""),0))"),1.0) -> 1 | D22: =IFERROR(__xludf.DUMMYFUNCTION("IF(D13="""","""",RANK(D13,FILTER($B13:$E13,$B13:$E13<>""""),0))"),"") | E22: =IFERROR(__xludf.DUMMYFUNCTION("IF(E13="""","""",RANK(E13,FILTER($B13:$E13,$B13:$E13<>""""),0))"),2.0) -> 2

Sheet 2026 Player Stats
A1: Player | B1: Times Drafted | C1: Avg Score | D1: High Score | E1: Low Score | F1: Winning Lineups | G1: Runner-up Lineups | H1: Refresh Player Stats | I1: TRUE | J1: Sort By | K1: Avg Score
A2: Deni Avdija | B2: 1 | C2: 66.4 | D2: 66.4 | E2: 66.4 | F2: 1 | G2: 0 | H2: 1 | I2: Player stats refreshed | J2: 66.4 | K2: Descending
A3: LaMelo Ball | B3: 1 | C3: 52 | D3: 52 | E3: 52 | F3: 0 | G3: 1 | H3: Last Refresh | I3: Sorted by Avg Score (Descending) | J3: Direction
A4: Miles Bridges | B4: 1 | C4: 49.8 | D4: 49.8 | E4: 49.8 | F4: 1 | G4: 0 | H4: 1 | I4: 0 | J4: 49.8
A5: Tyrese Maxey | B5: 1 | C5: 43.4 | D5: 43.4 | E5: 43.4 | F5: 0 | G5: 0 | H5: 0 | I5: 0 | J5: 43.4
A6: Stephen Curry | B6: 1 | C6: 41.2 | D6: 41.2 | E6: 41.2 | F6: 0 | G6: 0 | H6: 0 | I6: 0 | J6: 41.2
A7: Brandon Miller | B7: 1 | C7: 39.5 | D7: 39.5 | E7: 39.5 | F7: 0 | G7: 1 | H7: 0 | I7: 1 | J7: 39.5
A8: Desmond Bane | B8: 1 | C8: 39.1 | D8: 39.1 | E8: 39.1 | F8: 0 | G8: 1 | H8: Status | I8: 1 | J8: 39.1
A9: Darius Garland | B9: 1 | C9: 39 | D9: 39 | E9: 39 | F9: 1 | G9: 0 | H9: 1 | I9: 0 | J9: 39
A10: Kristaps Porzingis | B10: 1 | C10: 38.5 | D10: 38.5 | E10: 38.5 | F10: 0 | G10: 1 | H10: 0 | I10: 1 | J10: 38.5
A11: Dillon Brooks | B11: 1 | C11: 38.4 | D11: 38.4 | E11: 38.4 | F11: 0 | G11: 0 | H11: 0 | I11: 0 | J11: 38.4
A12: Tyler Herro | B12: 1 | C12: 33.6 | D12: 33.6 | E12: 33.6 | F12: 0 | G12: 0 | H12: 0 | I12: 0 | J12: 33.6
A13: Paul George | B13: 1 | C13: 33.5 | D13: 33.5 | E13: 33.5 | F13: 1 | G13: 0 | H13: 1 | I13: 0 | J13: 33.5
A14: Devin Booker | B14: 1 | C14: 29.2 | D14: 29.2 | E14: 29.2 | F14: 1 | G14: 0 | H14: 1 | I14: 0 | J14: 29.2
A15: Kawhi Leonard | B15: 1 | C15: 28.9 | D15: 28.9 | E15: 28.9 | F15: 0 | G15: 0 | H15: 0 | I15: 0 | J15: 28.9
A16: Paolo Banchero | B16: 1 | C16: 26 | D16: 26 | E16: 26 | F16: 0 | G16: 0 | H16: 0 | I16: 0 | J16: 26
A17: Wendell Carter Jr. | B17: 1 | C17: 25.7 | D17: 25.7 | E17: 25.7 | F17: 0 | G17: 0 | H17: 0 | I17: 0 | J17: 25.7
A18: Jerami Grant | B18: 1 | C18: 21.4 | D18: 21.4 | E18: 21.4 | F18: 0 | G18: 0 | H18: 0 | I18: 0 | J18: 21.4
A19: Franz Wagner | B19: 1 | C19: 21.3 | D19: 21.3 | E19: 21.3 | F19: 0 | G19: 0 | H19: 0 | I19: 0 | J19: 21.3
A20: Kon Knueppel | B20: 1 | C20: 13.5 | D20: 13.5 | E20: 13.5 | F20: 0 | G20: 0 | H20: 0 | I20: 0 | J20: 13.5
A21: Bam Adebayo | B21: 1 | C21: 13.1 | D21: 13.1 | E21: 13.1 | F21: 0 | G21: 1 | H21: 0 | I21: 1 | J21: 13.1

Sheet 2025 Standings
A1: Name | B1: Wins | C1: Runner-ups | D1: Avg Finish | E1: Avg Score | F1: High Score | G1: Low Score
A2: Andy | B2: =SUMPRODUCT(--(B11:B44> C11:C44), --(B11:B44> D11:D44), --(B11:B44> E11:E44)) -> 5 | C2: =COUNTIF(B48:B81,2) -> 5 | D2: =AVERAGEIF(B48:B81,"<>#N/A") -> 2.68 | E2: =AVERAGEIF(B11:B44,">0") -> 160.728 | F2: =MAXIFS(B11:B44,B11:B44,">0") -> 218 | G2: =MINIFS(B11:B44,B11:B44,">0") -> 108.4
A3: Josh | B3: =SUMPRODUCT(--(C11:C44> B11:B44), --(C11:C44> D11:D44), --(C11:C44> E11:E44)) -> 7 | C3: =COUNTIF(C48:C81,2) -> 7 | D3: =AVERAGEIF(C48:C81,"<>#N/A") -> 2.4 | E3: =AVERAGEIF(C11:C44,">0") -> 167.292 | F3: =MAXIFS(C11:C44,C11:C44,">0") -> 226.1 | G3: =MINIFS(C11:C44,C11:C44,">0") -> 120.6
A4: Jon | B4: =SUMPRODUCT(--(D11:D44> C11:C44), --(D11:D44> B11:B44), --(D11:D44> E11:E44)) -> 3 | C4: =COUNTIF(D48:D81,2) -> 8 | D4: =AVERAGEIF(D48:D81,"<>#N/A") -> 2.7083333 | E4: =AVERAGEIF(D11:D44,">0") -> 161.42083 | F4: =MAXIFS(D11:D44,D11:D44,">0") -> 214.4 | G4: =MINIFS(D11:D44,D11:D44,">0") -> 116.7
A5: Mark | B5: =SUMPRODUCT(--(E11:E44> C11:C44), --(E11:E44> D11:D44), --(E11:E44> B11:B44)) -> 10 | C5: =COUNTIF(E48:E81,2) -> 5 | D5: =AVERAGEIF(E48:E81,"<>#N/A") -> 2.16 | E5: =AVERAGEIF(E11:E44,">0") -> 169.276 | F5: =MAXIFS(E11:E44,E11:E44,">0") -> 231.4 | G5: =MINIFS(E11:E44,E11:E44,">0") -> 107.5
A9: Scores
A10: Date | B10: Andy | C10: Josh | D10: Jon | E10: Mark
A11: 45766 | B11: =VLOOKUP("Andy",'41925'!$A$1:$I$35, 9,0) -> 201.4 | C11: =VLOOKUP("Josh",'41925'!$A$1:$I$35, 9,0) -> 226.1 | D11: =VLOOKUP("Jon",'41925'!$A$1:$I$35, 9,0) -> 200.8 | E11: =VLOOKUP("Mark",'41925'!$A$1:$I$35, 9,0) -> 177.3
A12: 45767 | B12: =VLOOKUP("Andy",'42025'!$A$1:$I$35, 9,0) -> 177.4 | C12: =VLOOKUP("Josh",'42025'!$A$1:$I$35, 9,0) -> 177.3 | D12: =VLOOKUP("Jon",'42025'!$A$1:$I$35, 9,0) -> 164.4 | E12: =VLOOKUP("Mark",'42025'!$A$1:$I$35, 9,0) -> 165
A13: 45768 | B13: =VLOOKUP("Andy",'42125'!$A$1:$I$35, 9,0) -> 141.5 | C13: =VLOOKUP("Josh",'42125'!$A$1:$I$35, 9,0) -> 153.6 | D13: =VLOOKUP("Jon",'42125'!$A$1:$I$35, 9,0) -> 134.5 | E13: =VLOOKUP("Mark",'42125'!$A$1:$I$35, 9,0) -> 160.9
A14: 45769 | B14: =VLOOKUP("Andy",'42225'!$A$1:$I$35, 9,0) -> 205.1 | C14: =VLOOKUP("Josh",'42225'!$A$1:$I$35, 9,0) -> 161.1 | D14: =VLOOKUP("Jon",'42225'!$A$1:$I$35, 9,0) -> 172.3 | E14: =VLOOKUP("Mark",'42225'!$A$1:$I$35, 9,0) -> 180.3
A15: 45770 | B15: =VLOOKUP("Andy",'42325'!$A$1:$I$35, 9,0) -> 149.2 | C15: =VLOOKUP("Josh",'42325'!$A$1:$I$35, 9,0) -> 184.4 | D15: =VLOOKUP("Jon",'42325'!$A$1:$I$35, 9,0) -> 183.6 | E15: =VLOOKUP("Mark",'42325'!$A$1:$I$35, 9,0) -> 162.2
A16: 45771 | B16: =VLOOKUP("Andy",'42425'!$A$1:$I$35, 9,0) -> 171.5 | C16: =VLOOKUP("Josh",'42425'!$A$1:$I$35, 9,0) -> 186.7 | D16: =VLOOKUP("Jon",'42425'!$A$1:$I$35, 9,0) -> 168.7 | E16: =VLOOKUP("Mark",'42425'!$A$1:$I$35, 9,0) -> 193.3
A17: 45772 | B17: =VLOOKUP("Andy",'42525'!$A$1:$I$35, 9,0) -> 169 | C17: =VLOOKUP("Josh",'42525'!$A$1:$I$35, 9,0) -> 151 | D17: =VLOOKUP("Jon",'42525'!$A$1:$I$35, 9,0) -> 152.4 | E17: =VLOOKUP("Mark",'42525'!$A$1:$I$35, 9,0) -> 203.1
A18: 45773 | B18: =VLOOKUP("Andy",'42625'!$A$1:$I$35, 9,0) -> 201.7 | C18: =VLOOKUP("Josh",'42625'!$A$1:$I$35, 9,0) -> 181.3 | E18: =VLOOKUP("Mark",'42625'!$A$1:$I$35, 9,0) -> 187.1
A19: 45774 | B19: =VLOOKUP("Andy",'42725'!$A$1:$I$35, 9,0) -> 189.2 | C19: =VLOOKUP("Josh",'42725'!$A$1:$I$35, 9,0) -> 191.8 | D19: =VLOOKUP("Jon",'42725'!$A$1:$I$35, 9,0) -> 214.4 | E19: =VLOOKUP("Mark",'42725'!$A$1:$I$35, 9,0) -> 231.4
A20: 45775 | B20: =VLOOKUP("Andy",'42825'!$A$1:$I$35, 9,0) -> 147.8 | C20: =VLOOKUP("Josh",'42825'!$A$1:$I$35, 9,0) -> 120.6 | D20: =VLOOKUP("Jon",'42825'!$A$1:$I$35, 9,0) -> 132.2 | E20: =VLOOKUP("Mark",'42825'!$A$1:$I$35, 9,0) -> 107.5
A21: 45776 | B21: =VLOOKUP("Andy",'42925'!$A$1:$I$35, 9,0) -> 218 | C21: =VLOOKUP("Josh",'42925'!$A$1:$I$35, 9,0) -> 173.1 | D21: =VLOOKUP("Jon",'42925'!$A$1:$I$35, 9,0) -> 208 | E21: =VLOOKUP("Mark",'42925'!$A$1:$I$35, 9,0) -> 206.5
A22: 45777 | B22: =VLOOKUP("Andy",'43025'!$A$1:$I$35, 9,0) -> 108.4 | C22: =VLOOKUP("Josh",'43025'!$A$1:$I$35, 9,0) -> 164.3 | D22: =VLOOKUP("Jon",'43025'!$A$1:$I$35, 9,0) -> 177.8 | E22: =VLOOKUP("Mark",'43025'!$A$1:$I$35, 9,0) -> 134
A23: 45778 | B23: =VLOOKUP("Andy",'5125'!$A$1:$I$35, 9,0) -> 155.9 | C23: =VLOOKUP("Josh",'5125'!$A$1:$I$35, 9,0) -> 176.3 | D23: =VLOOKUP("Jon",'5125'!$A$1:$I$35, 9,0) -> 178 | E23: =VLOOKUP("Mark",'5125'!$A$1:$I$35, 9,0) -> 164.4
A24: 45779 | B24: =VLOOKUP("Andy",'5225'!$A$1:$I$35, 9,0) -> 157.4 | C24: =VLOOKUP("Josh",'5225'!$A$1:$I$35, 9,0) -> 164.6 | D24: =VLOOKUP("Jon",'5225'!$A$1:$I$35, 9,0) -> 127.3 | E24: =VLOOKUP("Mark",'5225'!$A$1:$I$35, 9,0) -> 167.3
A25: 45780
A26: 45781 | B26: =VLOOKUP("Andy",'5425'!$A$1:$I$35, 9,0) -> 153.9 | C26: =VLOOKUP("Josh",'5425'!$A$1:$I$35, 9,0) -> 138.8 | D26: =VLOOKUP("Jon",'5425'!$A$1:$I$35, 9,0) -> 158.3 | E26: =VLOOKUP("Mark",'5425'!$A$1:$I$35, 9,0) -> 192.4
A27: 45782 | B27: =VLOOKUP("Andy",'5525'!$A$1:$I$35, 9,0) -> 193.1 | C27: =VLOOKUP("Josh",'5525'!$A$1:$I$35, 9,0) -> 172 | D27: =VLOOKUP("Jon",'5525'!$A$1:$I$35, 9,0) -> 195.7 | E27: =VLOOKUP("Mark",'5525'!$A$1:$I$35, 9,0) -> 144.2
A28: 45783 | B28: =VLOOKUP("Andy",'5625'!$A$1:$I$35, 9,0) -> 137.4 | C28: =VLOOKUP("Josh",'5625'!$A$1:$I$35, 9,0) -> 219.6 | D28: =VLOOKUP("Jon",'5625'!$A$1:$I$35, 9,0) -> 141.3 | E28: =VLOOKUP("Mark",'5625'!$A$1:$I$35, 9,0) -> 159.6
A29: 45784 | B29: =VLOOKUP("Andy",'5725'!$A$1:$I$35, 9,0) -> 165.4 | C29: =VLOOKUP("Josh",'5725'!$A$1:$I$35, 9,0) -> 126 | D29: =VLOOKUP("Jon",'5725'!$A$1:$I$35, 9,0) -> 123.2 | E29: =VLOOKUP("Mark",'5725'!$A$1:$I$35, 9,0) -> 169.6
A30: 45785 | B30: =VLOOKUP("Andy",'5825'!$A$1:$I$35, 9,0) -> 147.3 | C30: =VLOOKUP("Josh",'5825'!$A$1:$I$35, 9,0) -> 193.6 | D30: =VLOOKUP("Jon",'5825'!$A$1:$I$35, 9,0) -> 184.9 | E30: =VLOOKUP("Mark",'5825'!$A$1:$I$35, 9,0) -> 156.3
A31: 45786
A32: 45787 | B32: =VLOOKUP("Andy",'51025'!$A$1:$I$35, 9,0) -> 122 | C32: =VLOOKUP("Josh",'51025'!$A$1:$I$35, 9,0) -> 186.9 | D32: =VLOOKUP("Jon",'51025'!$A$1:$I$35, 9,0) -> 138.6 | E32: =VLOOKUP("Mark",'51025'!$A$1:$I$35, 9,0) -> 121.5
A33: 45788 | B33: =VLOOKUP("Andy",'51125'!$A$1:$I$35, 9,0) -> 122.2 | C33: =VLOOKUP("Josh",'51125'!$A$1:$I$35, 9,0) -> 149.5 | D33: =VLOOKUP("Jon",'51125'!$A$1:$I$35, 9,0) -> 116.7 | E33: =VLOOKUP("Mark",'51125'!$A$1:$I$35, 9,0) -> 138.7
A34: 45789 | B34: =VLOOKUP("Andy",'51225'!$A$1:$I$35, 9,0) -> 161.5 | C34: =VLOOKUP("Josh",'51225'!$A$1:$I$35, 9,0) -> 122.1 | D34: =VLOOKUP("Jon",'51225'!$A$1:$I$35, 9,0) -> 155.6 | E34: =VLOOKUP("Mark",'51225'!$A$1:$I$35, 9,0) -> 170.7
A35: 45790 | B35: =VLOOKUP("Andy",'51325'!$A$1:$I$35, 9,0) -> 154.5 | C35: =VLOOKUP("Josh",'51325'!$A$1:$I$35, 9,0) -> 154.7 | D35: =VLOOKUP("Jon",'51325'!$A$1:$I$35, 9,0) -> 144.5 | E35: =VLOOKUP("Mark",'51325'!$A$1:$I$35, 9,0) -> 199.7
A36: 45791 | B36: =VLOOKUP("Andy",'51425'!$A$1:$I$35, 9,0) -> 132.7 | C36: =VLOOKUP("Josh",'51425'!$A$1:$I$35, 9,0) -> 173.1 | D36: =VLOOKUP("Jon",'51425'!$A$1:$I$35, 9,0) -> 158.9 | E36: =VLOOKUP("Mark",'51425'!$A$1:$I$35, 9,0) -> 172.4
A37: 45792 | B37: =VLOOKUP("Andy",'51525'!$A$1:$I$35, 9,0) -> 134.7 | C37: =VLOOKUP("Josh",'51525'!$A$1:$I$35, 9,0) -> 133.8 | D37: =VLOOKUP("Jon",'51525'!$A$1:$I$35, 9,0) -> 142 | E37: =VLOOKUP("Mark",'51525'!$A$1:$I$35, 9,0) -> 166.5
A38: 45793
A39: 45794
A40: 45795
A41: 45796
A42: 45797
A43: 45798
...

Sheet NBA Player List
A1: Players | H1: Score
A2: Aaron Gordon | B2: 14 | C2: 6 | D2: 1 | E2: 0 | F2: 0 | G2: 1 | H2: =sum(B2+1.2*C2+1.5*D2+2*E2+2*F2)-G2 -> 21.7 | K2: Players | L2: Avg | M2: Median | N2: Max | O2: Min | P2: Times Drafted | R2: *through 5/16/25
A3: Aaron Gordon | B3: 25 | C3: 8 | D3: 1 | E3: 2 | F3: 0 | G3: 3 | H3: 37.1 | L3: #DIV/0! | M3: #NUM! | N3: 0 | O3: 0 | P3: 0
A4: Aaron Gordon | B4: 15 | C4: 7 | D4: 0 | E4: 0 | F4: 0 | G4: 2 | H4: =sum(B4+1.2*C4+1.5*D4+2*E4+2*F4)-G4 -> 21.4 | K4: Giannis Antetekoumpo | L4: 60.78 | M4: 57.4 | N4: 74.5 | O4: 52.9 | P4: 5
A5: Alperun Sengun | B5: 31 | C5: 10 | D5: 5 | E5: 2 | F5: 0 | G5: 0 | H5: =sum(B5+1.2*C5+1.5*D5+2*E5+2*F5)-G5 -> 54.5 | K5: Nikola Jokic | L5: 56.807692 | M5: 54.4 | N5: 77.2 | O5: 33.6 | P5: 13 | T5: Player Name | U5: Number of Wins
A6: Alperun Sengun | B6: 26 | C6: 9 | D6: 1 | E6: 3 | F6: 0 | G6: 5 | H6: =sum(B6+1.2*C6+1.5*D6+2*E6+2*F6)-G6 -> 39.3 | K6: Jayson Tatum | L6: 52.6125 | M6: 51 | N6: 66.6 | O6: 42.3 | P6: 8 | T6: Karl-Anthony Towns | U6: 6
A7: Alperun Sengun | B7: 17 | C7: 16 | D7: 7 | E7: 2 | F7: 0 | G7: 3 | H7: =sum(B7+1.2*C7+1.5*D7+2*E7+2*F7)-G7 -> 47.7 | K7: LeBron James | L7: 49.6 | M7: 46.7 | N7: 63 | O7: 35.5 | P7: 5 | T7: Jamal Murray | U7: 5
A8: Alperun Sengun | B8: 15 | C8: 11 | D8: 4 | E8: 0 | F8: 0 | G8: 1 | H8: =sum(B8+1.2*C8+1.5*D8+2*E8+2*F8)-G8 -> 33.2 | K8: Shai Gilgeous-Alexander | L8: 47.54 | M8: 47.95 | N8: 62 | O8: 28.1 | P8: 10 | T8: Steph Curry | U8: 4
A9: Alperun Sengun | B9: 15 | C9: 9 | D9: 9 | E9: 2 | F9: 2 | G9: 1 | H9: =sum(B9+1.2*C9+1.5*D9+2*E9+2*F9)-G9 -> 46.3 | K9: Cade Cunningham | L9: 47.366667 | M9: 49.65 | N9: 54.9 | O9: 30.4 | P9: 6 | T9: Jimmy Butler | U9: 4
A10: Amen Thompson | B10: 11 | C10: 1 | D10: 3 | E10: 0 | F10: 0 | G10: 0 | H10: =sum(B10+1.2*C10+1.5*D10+2*E10+2*F10)-G10 -> 16.7 | K10: Anthony Edwards | L10: 47.25 | M10: 46.15 | N10: 63.8 | O10: 30.2 | P10: 10 | T10: Jayson Tatum | U10: 4
A11: Amen Thompson | B11: 8 | C11: 9 | D11: 6 | E11: 1 | F11: 1 | G11: 2 | H11: =sum(B11+1.2*C11+1.5*D11+2*E11+2*F11)-G11 -> 29.8 | K11: Luka Doncic | L11: 46.5 | M11: 47.1 | N11: 56.9 | O11: 36.4 | P11: 5 | T11: Jalen Williams | U11: 4
A12: Amen Thompson | B12: 17 | C12: 9 | D12: 2 | E12: 1 | F12: 0 | G12: 1 | H12: =sum(B12+1.2*C12+1.5*D12+2*E12+2*F12)-G12 -> 31.8 | K12: Paolo Banchero | L12: 45.58 | M12: 41.9 | N12: 57.3 | O12: 35.8 | P12: 5 | T12: Rudy Gobert | U12: 3
A13: Amen Thompson | B13: 25 | C13: 6 | D13: 3 | E13: 5 | F13: 3 | G13: 3 | H13: =sum(B13+1.2*C13+1.5*D13+2*E13+2*F13)-G13 -> 49.7 | K13: Alperun Sengun | L13: 45.442857 | M13: 46.3 | N13: 54.5 | O13: 33.2 | P13: 7 | T13: OG Anunoby | U13: 3
A14: Andrew Nembhard | B14: 6 | C14: 1 | D14: 5 | E14: 1 | F14: 0 | G14: 0 | H14: =sum(B14+1.2*C14+1.5*D14+2*E14+2*F14)-G14 -> 16.7 | K14: Jalen Brunson | L14: 43.783333 | M14: 44.35 | N14: 62 | O14: 26.1 | P14: 12 | T14: Michael Porter Jr. | U14: 3
A15: Andrew Wiggins | B15: 10 | C15: 1 | D15: 3 | E15: 0 | F15: 3 | G15: 2 | H15: =sum(B15+1.2*C15+1.5*D15+2*E15+2*F15)-G15 -> 19.7 | K15: Donovan Mitchell | L15: 43.677778 | M15: 47.2 | N15: 72.5 | O15: 15.2 | P15: 9 | T15: Julius Randle | U15: 3
A16: Andrew Wiggins | B16: 12 | C16: 5 | D16: 1 | E16: 0 | F16: 0 | G16: 3 | H16: =sum(B16+1.2*C16+1.5*D16+2*E16+2*F16)-G16 -> 16.5 | K16: Kawhi Leonard | L16: 42.728571 | M16: 41.2 | N16: 55.1 | O16: 31.2 | P16: 7 | T16: Josh Hart | U16: 3
A17: Anthony Edwards | B17: 29 | C17: 8 | D17: 8 | E17: 2 | F17: 1 | G17: 2 | H17: =sum(B17+1.2*C17+1.5*D17+2*E17+2*F17)-G17 -> 54.6 | K17: Franz Wagner | L17: 41.16 | M17: 37.8 | N17: 55.4 | O17: 35.1 | P17: 5 | T17: Jalen Brunson | U17: 3
A18: Anthony Edwards | B18: 22 | C18: 8 | D18: 9 | E18: 1 | F18: 0 | G18: 1 | H18: 46.1 | K18: James Harden | L18: 40.514286 | M18: 39.7 | N18: 55.7 | O18: 28.1 | P18: 7 | T18: Evan Mobley | U18: 3
A19: Anthony Edwards | B19: 25 | C19: 6 | D19: 0 | E19: 0 | F19: 0 | G19: 2 | H19: =sum(B19+1.2*C19+1.5*D19+2*E19+2*F19)-G19 -> 30.2 | K19: Tyrese Haliburton | L19: 38.95 | M19: 40.2 | N19: 56.5 | O19: 10.5 | P19: 10 | T19: Donovan Mitchell | U19: 3
A20: Anthony Edwards | B20: 43 | C20: 9 | D20: 6 | E20: 0 | F20: 1 | G20: 1 | H20: =sum(B20+1.2*C20+1.5*D20+2*E20+2*F20)-G20 -> 63.8 | K20: Julius Randle | L20: 38.73 | M20: 40.5 | N20: 56 | O20: 22.5 | P20: 10 | T20: Derrick White | U20: 3
A21: Anthony Edwards | B21: 15 | C21: 11 | D21: 8 | E21: 3 | F21: 0 | G21: 0 | H21: =sum(B21+1.2*C21+1.5*D21+2*E21+2*F21)-G21 -> 46.2 | K21: Jamal Murray | L21: 37.207692 | M21: 35.2 | N21: 66.5 | O21: 20.3 | P21: 13 | T21: Brandin Podziemski | U21: 3
A22: Ausar Thompson | B22: 5 | C22: 5 | D22: 0 | E22: 2 | F22: 0 | G22: 2 | H22: =sum(B22+1.2*C22+1.5*D22+2*E22+2*F22)-G22 -> 13 | K22: Jalen Williams | L22: 37.18 | M22: 37.1 | N22: 44.7 | O22: 28.1 | P22: 10 | T22: Anthony Edwards | U22: 3
A23: Austin Reaves | B23: 16 | C23: 5 | D23: 5 | E23: 0 | F23: 0 | G23: 1 | H23: =sum(B23+1.2*C23+1.5*D23+2*E23+2*F23)-G23 -> 28.5 | K23: Steph Curry | L23: 36.7375 | M23: 39.1 | N23: 61.9 | O23: 14.7 | P23: 8 | T23: Amen Thompson | U23: 3
A24: Austin Reaves | B24: 20 | C24: 7 | D24: 4 | E24: 0 | F24: 1 | G24: 4 | H24: =sum(B24+1.2*C24+1.5*D24+2*E24+2*F24)-G24 -> 32.4 | K24: Jimmy Butler | L24: 36.736364 | M24: 41.1 | N24: 51.4 | O24: 5.4 | P24: 11 | T24: Tyrese Haliburton | U24: 2
A25: Austin Reaves | B25: 16 | C25: 3 | D25: 3 | E25: 0 | F25: 0 | G25: 2 | H25: 22.1 | K25: Bam Adebayo | L25: 36.575 | M25: 36.85 | N25: 44.3 | O25: 28.3 | P25: 4 | T25: Shai Gilgeous-Alexander | U25: 2
A26: Austin Reaves | B26: 12 | C26: 5 | D26: 2 | E26: 0 | F26: 0 | G26: 6 | H26: =sum(B26+1.2*C26+1.5*D26+2*E26+2*F26)-G26 -> 15 | K26: Karl-Anthony Towns | L26: 36.475 | M26: 35.8 | N26: 55.7 | O26: 19.2 | P26: 12 | T26: Russell Westbrook | U26: 2
A27: Bam Adebayo | B27: 24 | C27: 9 | D27: 3 | E27: 2 | F27: 1 | G27: 1 | H27: =sum(B27+1.2*C27+1.5*D27+2*E27+2*F27)-G27 -> 44.3 | K27: Jaylen Brown | L27: 35.372727 | M27: 33.2 | N27: 54.5 | O27: 25.7 | P27: 11 | T27: Paolo Banchero | U27: 2
A28: Bam Adebayo | B28: 13 | C28: 12 | D28: 4 | E28: 1 | F28: 0 | G28: 3 | H28: =sum(B28+1.2*C28+1.5*D28+2*E28+2*F28)-G28 -> 32.4 | K28: Ivica Zubac | L28: 34.885714 | M28: 36.4 | N28: 46.4 | O28: 24.2 | P28: 7 | T28: Mikal Bridges | U28: 2
A29: Bam Adebayo | B29: 22 | C29: 9 | D29: 1 | E29: 0 | F29: 0 | G29: 6 | H29: =sum(B29+1.2*C29+1.5*D29+2*E29+2*F29)-G29 -> 28.3 | K29: Chet Holmgren | L29: 34.17 | M29: 35.15 | N29: 42.2 | O29: 21.6 | P29: 10 | T29: Max Strus | U29: 2
A30: Bam Adebayo | B30: 11 | C30: 14 | D30: 9 | E30: 1 | F30: 0 | G30: 2 | H30: =sum(B30+1.2*C30+1.5*D30+2*E30+2*F30)-G30 -> 41.3 | K30: Fred VanVleet | L30: 34.06 | M30: 31.2 | N30: 48.6 | O30: 25.2 | P30: 5 | T30: Jaylen Brown | U30: 2
A31: Bobby Portis | B31: 10 | C31: 8 | D31: 3 | E31: 1 | F31: 1 | G31: 3 | H31: =sum(B31+1.2*C31+1.5*D31+2*E31+2*F31)-G31 -> 25.1 | K31: Amen Thompson | L31: 33.45 | M31: 30.8 | N31: 49.7 | O31: 16.7 | P31: 6 | T31: Jarrett Allen | U31: 2
A32: Brandin Podziemski | B32: 26 | C32: 5 | D32: 5 | E32: 2 | F32: 1 | G32: 2 | H32: =sum(B32+1.2*C32+1.5*D32+2*E32+2*F32)-G32 -> 43.5 | K32: Josh Hart | L32: 33.063636 | M32: 34.7 | N32: 40.2 | O32: 23.3 | P32: 11 | T32: Jaren Jackson Jr. | U32: 2
A33: Buddy Hield | B33: 4 | C33: 2 | D33: 1 | E33: 1 | F33: 1 | G33: 0 | H33: =sum(B33+1.2*C33+1.5*D33+2*E33+2*F33)-G33 -> 11.9 | K33: Jalen Duren | L33: 32.216667 | M33: 32.05 | N33: 37.8 | O33: 25.7 | P33: 6 | T33: Jalen Green | U33: 2
A34: Cade Cunningham | B34: 33 | C34: 12 | D34: 3 | E34: 2 | F34: 0 | G34: 5 | H34: =sum(B34+1.2*C34+1.5*D34+2*E34+2*F34)-G34 -> 50.9 | K34: Evan Mobley | L34: 32.1875 | M34: 32.8 | N34: 51.6 | O34: 16 | P34: 8 | T34: Jaden McDaniels | U34: 2
A35: Cade Cunningham | B35: 25 | C35: 10 | D35: 10 | E35: 0 | F35: 4 | G35: 7 | H35: =sum(B35+1.2*C35+1.5*D35+2*E35+2*F35)-G35 -> 53 | K35: Pascal Siakam | L35: 31.7 | M35: 30.95 | N35: 45.7 | O35: 14.3 | P35: 10 | T35: Desmond Bane | U35: 2
A36: Cade Cunningham | B36: 21 | C36: 6 | D36: 12 | E36: 0 | F36: 0 | G36: 6 | H36: 30.4 | K36: Derrick White | L36: 31.59 | M36: 32.4 | N36: 44.6 | O36: 13.2 | P36: 10 | T36: Damian Lillard | U36: 2
A37: Cade Cunningham | B37: 24 | C37: 7 | D37: 11 | E37: 4 | F37: 2 | G37: 6 | H37: =sum(B37+1.2*C37+1.5*D37+2*E37+2*F37)-G37 -> 54.9 | K37: Mikal Bridges | L37: 30.854545 | M37: 32.3 | N37: 43.9 | O37: 17.9 | P37: 11 | T37: Christian Braun | U37: 2
A38: Cade Cunningham | B38: 24 | C38: 8 | D38: 8 | E38: 2 | F38: 1 | G38: 5 | H38: =sum(B38+1.2*C38+1.5*D38+2*E38+2*F38)-G38 -> 46.6 | K38: Myles Turner | L38: 30.211111 | M38: 28.9 | N38: 45.1 | O38: 10.6 | P38: 9 | T38: Cade Cunningham | U38: 2
A39: Chet Holmgren | B39: 19 | C39: 10 | D39: 2 | E39: 1 | F39: 2 | G39: 0 | H39: =sum(B39+1.2*C39+1.5*D39+2*E39+2*F39)-G39 -> 40 | K39: Jaren Jackson Jr. | L39: 29.466667 | M39: 33.2 | N39: 34.4 | O39: 20.8 | P39: 3 | T39: Buddy Hield | U39: 2
A40: Chet Holmgren | B40: 11 | C40: 2 | D40: 1 | E40: 2 | F40: 4 | G40: 1 | H40: =sum(B40+1.2*C40+1.5*D40+2*E40+2*F40)-G40 -> 25.9 | K40: Aaron Gordon | L40: 29.24 | M40: 26.7 | N40: 41.2 | O40: 18.5 | P40: 10 | T40: Bam Adebayo | U40: 2
...

Sheet Daily_Template
A1: Start Date | C1: Update Stats | E1: Last Update | K1: Completed Games | M1: In Progress
A2: End Date | C2: Create Today Tab | E2: Status | K2: Andy | M2: 0/5
K3: Josh | M3: 0/5
A4: Andy | I4: =I11 -> 0 | K4: Jon | M4: 0/5
A5: Position | B5: Player | C5: Points (1) | D5: Rebounds (1.2) | E5: Assists (1.5) | F5: Steals (2) | G5: Blocks (2) | H5: Turnovers (-1) | I5: Total | K5: Mark | M5: 0/5
A6: G | C6: =IF($B6="","",SUMIFS(Raw_Stats!$C:$C,Raw_Stats!$A:$A,">="&$B$1,Raw_Stats!$A:$A,"<="&$B$2,Raw_Stats!$B:$B,$B6)) | D6: =IF($B6="","",SUMIFS(Raw_Stats!$D:$D,Raw_Stats!$A:$A,">="&$B$1,Raw_Stats!$A:$A,"<="&$B$2,Raw_Stats!$B:$B,$B6)) | E6: =IF($B6="","",SUMIFS(Raw_Stats!$E:$E,Raw_Stats!$A:$A,">="&$B$1,Raw_Stats!$A:$A,"<="&$B$2,Raw_Stats!$B:$B,$B6)) | F6: =IF($B6="","",SUMIFS(Raw_Stats!$F:$F,Raw_Stats!$A:$A,">="&$B$1,Raw_Stats!$A:$A,"<="&$B$2,Raw_Stats!$B:$B,$B6)) | G6: =IF($B6="","",SUMIFS(Raw_Stats!$G:$G,Raw_Stats!$A:$A,">="&$B$1,Raw_Stats!$A:$A,"<="&$B$2,Raw_Stats!$B:$B,$B6)) | H6: =IF($B6="","",SUMIFS(Raw_Stats!$H:$H,Raw_Stats!$A:$A,">="&$B$1,Raw_Stats!$A:$A,"<="&$B$2,Raw_Stats!$B:$B,$B6)) | I6: =sum(C6+1.2*D6+1.5*E6+2*F6+2*G6)-H6 -> 0
A7: G | C7: =IF($B7="","",SUMIFS(Raw_Stats!$C:$C,Raw_Stats!$A:$A,">="&$B$1,Raw_Stats!$A:$A,"<="&$B$2,Raw_Stats!$B:$B,$B7)) | D7: =IF($B7="","",SUMIFS(Raw_Stats!$D:$D,Raw_Stats!$A:$A,">="&$B$1,Raw_Stats!$A:$A,"<="&$B$2,Raw_Stats!$B:$B,$B7)) | E7: =IF($B7="","",SUMIFS(Raw_Stats!$E:$E,Raw_Stats!$A:$A,">="&$B$1,Raw_Stats!$A:$A,"<="&$B$2,Raw_Stats!$B:$B,$B7)) | F7: =IF($B7="","",SUMIFS(Raw_Stats!$F:$F,Raw_Stats!$A:$A,">="&$B$1,Raw_Stats!$A:$A,"<="&$B$2,Raw_Stats!$B:$B,$B7)) | G7: =IF($B7="","",SUMIFS(Raw_Stats!$G:$G,Raw_Stats!$A:$A,">="&$B$1,Raw_Stats!$A:$A,"<="&$B$2,Raw_Stats!$B:$B,$B7)) | H7: =IF($B7="","",SUMIFS(Raw_Stats!$H:$H,Raw_Stats!$A:$A,">="&$B$1,Raw_Stats!$A:$A,"<="&$B$2,Raw_Stats!$B:$B,$B7)) | I7: =sum(C7+1.2*D7+1.5*E7+2*F7+2*G7)-H7 -> 0
A8: F/C | C8: =IF($B8="","",SUMIFS(Raw_Stats!$C:$C,Raw_Stats!$A:$A,">="&$B$1,Raw_Stats!$A:$A,"<="&$B$2,Raw_Stats!$B:$B,$B8)) | D8: =IF($B8="","",SUMIFS(Raw_Stats!$D:$D,Raw_Stats!$A:$A,">="&$B$1,Raw_Stats!$A:$A,"<="&$B$2,Raw_Stats!$B:$B,$B8)) | E8: =IF($B8="","",SUMIFS(Raw_Stats!$E:$E,Raw_Stats!$A:$A,">="&$B$1,Raw_Stats!$A:$A,"<="&$B$2,Raw_Stats!$B:$B,$B8)) | F8: =IF($B8="","",SUMIFS(Raw_Stats!$F:$F,Raw_Stats!$A:$A,">="&$B$1,Raw_Stats!$A:$A,"<="&$B$2,Raw_Stats!$B:$B,$B8)) | G8: =IF($B8="","",SUMIFS(Raw_Stats!$G:$G,Raw_Stats!$A:$A,">="&$B$1,Raw_Stats!$A:$A,"<="&$B$2,Raw_Stats!$B:$B,$B8)) | H8: =IF($B8="","",SUMIFS(Raw_Stats!$H:$H,Raw_Stats!$A:$A,">="&$B$1,Raw_Stats!$A:$A,"<="&$B$2,Raw_Stats!$B:$B,$B8)) | I8: =sum(C8+1.2*D8+1.5*E8+2*F8+2*G8)-H8 -> 0
A9: F/C | C9: =IF($B9="","",SUMIFS(Raw_Stats!$C:$C,Raw_Stats!$A:$A,">="&$B$1,Raw_Stats!$A:$A,"<="&$B$2,Raw_Stats!$B:$B,$B9)) | D9: =IF($B9="","",SUMIFS(Raw_Stats!$D:$D,Raw_Stats!$A:$A,">="&$B$1,Raw_Stats!$A:$A,"<="&$B$2,Raw_Stats!$B:$B,$B9)) | E9: =IF($B9="","",SUMIFS(Raw_Stats!$E:$E,Raw_Stats!$A:$A,">="&$B$1,Raw_Stats!$A:$A,"<="&$B$2,Raw_Stats!$B:$B,$B9)) | F9: =IF($B9="","",SUMIFS(Raw_Stats!$F:$F,Raw_Stats!$A:$A,">="&$B$1,Raw_Stats!$A:$A,"<="&$B$2,Raw_Stats!$B:$B,$B9)) | G9: =IF($B9="","",SUMIFS(Raw_Stats!$G:$G,Raw_Stats!$A:$A,">="&$B$1,Raw_Stats!$A:$A,"<="&$B$2,Raw_Stats!$B:$B,$B9)) | H9: =IF($B9="","",SUMIFS(Raw_Stats!$H:$H,Raw_Stats!$A:$A,">="&$B$1,Raw_Stats!$A:$A,"<="&$B$2,Raw_Stats!$B:$B,$B9)) | I9: =sum(C9+1.2*D9+1.5*E9+2*F9+2*G9)-H9 -> 0
A10: F/C | C10: =IF($B10="","",SUMIFS(Raw_Stats!$C:$C,Raw_Stats!$A:$A,">="&$B$1,Raw_Stats!$A:$A,"<="&$B$2,Raw_Stats!$B:$B,$B10)) | D10: =IF($B10="","",SUMIFS(Raw_Stats!$D:$D,Raw_Stats!$A:$A,">="&$B$1,Raw_Stats!$A:$A,"<="&$B$2,Raw_Stats!$B:$B,$B10)) | E10: =IF($B10="","",SUMIFS(Raw_Stats!$E:$E,Raw_Stats!$A:$A,">="&$B$1,Raw_Stats!$A:$A,"<="&$B$2,Raw_Stats!$B:$B,$B10)) | F10: =IF($B10="","",SUMIFS(Raw_Stats!$F:$F,Raw_Stats!$A:$A,">="&$B$1,Raw_Stats!$A:$A,"<="&$B$2,Raw_Stats!$B:$B,$B10)) | G10: =IF($B10="","",SUMIFS(Raw_Stats!$G:$G,Raw_Stats!$A:$A,">="&$B$1,Raw_Stats!$A:$A,"<="&$B$2,Raw_Stats!$B:$B,$B10)) | H10: =IF($B10="","",SUMIFS(Raw_Stats!$H:$H,Raw_Stats!$A:$A,">="&$B$1,Raw_Stats!$A:$A,"<="&$B$2,Raw_Stats!$B:$B,$B10)) | I10: =sum(C10+1.2*D10+1.5*E10+2*F10+2*G10)-H10 -> 0
B11: Totals | C11: =SUM(C6:C10) -> 0 | D11: =SUM(D6:D10)*1.2 -> 0 | E11: =SUM(E6:E10)*1.5 -> 0 | F11: =SUM(F6:F10)*2 -> 0 | G11: =SUM(G6:G10)*2 -> 0 | H11: =SUM(H6:H10) *-1 -> 0 | I11: =SUM(C11:H11) -> 0
A13: Jon | I13: =I20 -> 0
A14: Position | B14: Player | C14: Points (1) | D14: Rebounds (1.2) | E14: Assists (1.5) | F14: Steals (2) | G14: Blocks (2) | H14: Turnovers (-1) | I14: Total
A15: G | C15: =IF($B15="","",SUMIFS(Raw_Stats!$C:$C,Raw_Stats!$A:$A,">="&$B$1,Raw_Stats!$A:$A,"<="&$B$2,Raw_Stats!$B:$B,$B15)) | D15: =IF($B15="","",SUMIFS(Raw_Stats!$D:$D,Raw_Stats!$A:$A,">="&$B$1,Raw_Stats!$A:$A,"<="&$B$2,Raw_Stats!$B:$B,$B15)) | E15: =IF($B15="","",SUMIFS(Raw_Stats!$E:$E,Raw_Stats!$A:$A,">="&$B$1,Raw_Stats!$A:$A,"<="&$B$2,Raw_Stats!$B:$B,$B15)) | F15: =IF($B15="","",SUMIFS(Raw_Stats!$F:$F,Raw_Stats!$A:$A,">="&$B$1,Raw_Stats!$A:$A,"<="&$B$2,Raw_Stats!$B:$B,$B15)) | G15: =IF($B15="","",SUMIFS(Raw_Stats!$G:$G,Raw_Stats!$A:$A,">="&$B$1,Raw_Stats!$A:$A,"<="&$B$2,Raw_Stats!$B:$B,$B15)) | H15: =IF($B15="","",SUMIFS(Raw_Stats!$H:$H,Raw_Stats!$A:$A,">="&$B$1,Raw_Stats!$A:$A,"<="&$B$2,Raw_Stats!$B:$B,$B15)) | I15: =sum(C15+1.2*D15+1.5*E15+2*F15+2*G15)-H15 -> 0
A16: G | C16: =IF($B16="","",SUMIFS(Raw_Stats!$C:$C,Raw_Stats!$A:$A,">="&$B$1,Raw_Stats!$A:$A,"<="&$B$2,Raw_Stats!$B:$B,$B16)) | D16: =IF($B16="","",SUMIFS(Raw_Stats!$D:$D,Raw_Stats!$A:$A,">="&$B$1,Raw_Stats!$A:$A,"<="&$B$2,Raw_Stats!$B:$B,$B16)) | E16: =IF($B16="","",SUMIFS(Raw_Stats!$E:$E,Raw_Stats!$A:$A,">="&$B$1,Raw_Stats!$A:$A,"<="&$B$2,Raw_Stats!$B:$B,$B16)) | F16: =IF($B16="","",SUMIFS(Raw_Stats!$F:$F,Raw_Stats!$A:$A,">="&$B$1,Raw_Stats!$A:$A,"<="&$B$2,Raw_Stats!$B:$B,$B16)) | G16: =IF($B16="","",SUMIFS(Raw_Stats!$G:$G,Raw_Stats!$A:$A,">="&$B$1,Raw_Stats!$A:$A,"<="&$B$2,Raw_Stats!$B:$B,$B16)) | H16: =IF($B16="","",SUMIFS(Raw_Stats!$H:$H,Raw_Stats!$A:$A,">="&$B$1,Raw_Stats!$A:$A,"<="&$B$2,Raw_Stats!$B:$B,$B16)) | I16: =sum(C16+1.2*D16+1.5*E16+2*F16+2*G16)-H16 -> 0
A17: F/C | C17: =IF($B17="","",SUMIFS(Raw_Stats!$C:$C,Raw_Stats!$A:$A,">="&$B$1,Raw_Stats!$A:$A,"<="&$B$2,Raw_Stats!$B:$B,$B17)) | D17: =IF($B17="","",SUMIFS(Raw_Stats!$D:$D,Raw_Stats!$A:$A,">="&$B$1,Raw_Stats!$A:$A,"<="&$B$2,Raw_Stats!$B:$B,$B17)) | E17: =IF($B17="","",SUMIFS(Raw_Stats!$E:$E,Raw_Stats!$A:$A,">="&$B$1,Raw_Stats!$A:$A,"<="&$B$2,Raw_Stats!$B:$B,$B17)) | F17: =IF($B17="","",SUMIFS(Raw_Stats!$F:$F,Raw_Stats!$A:$A,">="&$B$1,Raw_Stats!$A:$A,"<="&$B$2,Raw_Stats!$B:$B,$B17)) | G17: =IF($B17="","",SUMIFS(Raw_Stats!$G:$G,Raw_Stats!$A:$A,">="&$B$1,Raw_Stats!$A:$A,"<="&$B$2,Raw_Stats!$B:$B,$B17)) | H17: =IF($B17="","",SUMIFS(Raw_Stats!$H:$H,Raw_Stats!$A:$A,">="&$B$1,Raw_Stats!$A:$A,"<="&$B$2,Raw_Stats!$B:$B,$B17)) | I17: =sum(C17+1.2*D17+1.5*E17+2*F17+2*G17)-H17 -> 0
A18: F/C | C18: =IF($B18="","",SUMIFS(Raw_Stats!$C:$C,Raw_Stats!$A:$A,">="&$B$1,Raw_Stats!$A:$A,"<="&$B$2,Raw_Stats!$B:$B,$B18)) | D18: =IF($B18="","",SUMIFS(Raw_Stats!$D:$D,Raw_Stats!$A:$A,">="&$B$1,Raw_Stats!$A:$A,"<="&$B$2,Raw_Stats!$B:$B,$B18)) | E18: =IF($B18="","",SUMIFS(Raw_Stats!$E:$E,Raw_Stats!$A:$A,">="&$B$1,Raw_Stats!$A:$A,"<="&$B$2,Raw_Stats!$B:$B,$B18)) | F18: =IF($B18="","",SUMIFS(Raw_Stats!$F:$F,Raw_Stats!$A:$A,">="&$B$1,Raw_Stats!$A:$A,"<="&$B$2,Raw_Stats!$B:$B,$B18)) | G18: =IF($B18="","",SUMIFS(Raw_Stats!$G:$G,Raw_Stats!$A:$A,">="&$B$1,Raw_Stats!$A:$A,"<="&$B$2,Raw_Stats!$B:$B,$B18)) | H18: =IF($B18="","",SUMIFS(Raw_Stats!$H:$H,Raw_Stats!$A:$A,">="&$B$1,Raw_Stats!$A:$A,"<="&$B$2,Raw_Stats!$B:$B,$B18)) | I18: =sum(C18+1.2*D18+1.5*E18+2*F18+2*G18)-H18 -> 0
A19: F/C | C19: =IF($B19="","",SUMIFS(Raw_Stats!$C:$C,Raw_Stats!$A:$A,">="&$B$1,Raw_Stats!$A:$A,"<="&$B$2,Raw_Stats!$B:$B,$B19)) | D19: =IF($B19="","",SUMIFS(Raw_Stats!$D:$D,Raw_Stats!$A:$A,">="&$B$1,Raw_Stats!$A:$A,"<="&$B$2,Raw_Stats!$B:$B,$B19)) | E19: =IF($B19="","",SUMIFS(Raw_Stats!$E:$E,Raw_Stats!$A:$A,">="&$B$1,Raw_Stats!$A:$A,"<="&$B$2,Raw_Stats!$B:$B,$B19)) | F19: =IF($B19="","",SUMIFS(Raw_Stats!$F:$F,Raw_Stats!$A:$A,">="&$B$1,Raw_Stats!$A:$A,"<="&$B$2,Raw_Stats!$B:$B,$B19)) | G19: =IF($B19="","",SUMIFS(Raw_Stats!$G:$G,Raw_Stats!$A:$A,">="&$B$1,Raw_Stats!$A:$A,"<="&$B$2,Raw_Stats!$B:$B,$B19)) | H19: =IF($B19="","",SUMIFS(Raw_Stats!$H:$H,Raw_Stats!$A:$A,">="&$B$1,Raw_Stats!$A:$A,"<="&$B$2,Raw_Stats!$B:$B,$B19)) | I19: =sum(C19+1.2*D19+1.5*E19+2*F19+2*G19)-H19 -> 0
B20: Totals | C20: =SUM(C15:C19) -> 0 | D20: =SUM(D15:D19)*1.2 -> 0 | E20: =SUM(E15:E19)*1.5 -> 0 | F20: =SUM(F15:F19)*2 -> 0 | G20: =SUM(G15:G19)*2 -> 0 | H20: =SUM(H15:H19) *-1 -> 0 | I20: =SUM(C20:H20) -> 0
A22: Mark | I22: =I29 -> 0
A23: Position | B23: Player | C23: Points (1) | D23: Rebounds (1.2) | E23: Assists (1.5) | F23: Steals (2) | G23: Blocks (2) | H23: Turnovers (-1) | I23: Total
A24: G | C24: =IF($B24="","",SUMIFS(Raw_Stats!$C:$C,Raw_Stats!$A:$A,">="&$B$1,Raw_Stats!$A:$A,"<="&$B$2,Raw_Stats!$B:$B,$B24)) | D24: =IF($B24="","",SUMIFS(Raw_Stats!$D:$D,Raw_Stats!$A:$A,">="&$B$1,Raw_Stats!$A:$A,"<="&$B$2,Raw_Stats!$B:$B,$B24)) | E24: =IF($B24="","",SUMIFS(Raw_Stats!$E:$E,Raw_Stats!$A:$A,">="&$B$1,Raw_Stats!$A:$A,"<="&$B$2,Raw_Stats!$B:$B,$B24)) | F24: =IF($B24="","",SUMIFS(Raw_Stats!$F:$F,Raw_Stats!$A:$A,">="&$B$1,Raw_Stats!$A:$A,"<="&$B$2,Raw_Stats!$B:$B,$B24)) | G24: =IF($B24="","",SUMIFS(Raw_Stats!$G:$G,Raw_Stats!$A:$A,">="&$B$1,Raw_Stats!$A:$A,"<="&$B$2,Raw_Stats!$B:$B,$B24)) | H24: =IF($B24="","",SUMIFS(Raw_Stats!$H:$H,Raw_Stats!$A:$A,">="&$B$1,Raw_Stats!$A:$A,"<="&$B$2,Raw_Stats!$B:$B,$B24)) | I24: =sum(C24+1.2*D24+1.5*E24+2*F24+2*G24)-H24 -> 0
A25: G | C25: =IF($B25="","",SUMIFS(Raw_Stats!$C:$C,Raw_Stats!$A:$A,">="&$B$1,Raw_Stats!$A:$A,"<="&$B$2,Raw_Stats!$B:$B,$B25)) | D25: =IF($B25="","",SUMIFS(Raw_Stats!$D:$D,Raw_Stats!$A:$A,">="&$B$1,Raw_Stats!$A:$A,"<="&$B$2,Raw_Stats!$B:$B,$B25)) | E25: =IF($B25="","",SUMIFS(Raw_Stats!$E:$E,Raw_Stats!$A:$A,">="&$B$1,Raw_Stats!$A:$A,"<="&$B$2,Raw_Stats!$B:$B,$B25)) | F25: =IF($B25="","",SUMIFS(Raw_Stats!$F:$F,Raw_Stats!$A:$A,">="&$B$1,Raw_Stats!$A:$A,"<="&$B$2,Raw_Stats!$B:$B,$B25)) | G25: =IF($B25="","",SUMIFS(Raw_Stats!$G:$G,Raw_Stats!$A:$A,">="&$B$1,Raw_Stats!$A:$A,"<="&$B$2,Raw_Stats!$B:$B,$B25)) | H25: =IF($B25="","",SUMIFS(Raw_Stats!$H:$H,Raw_Stats!$A:$A,">="&$B$1,Raw_Stats!$A:$A,"<="&$B$2,Raw_Stats!$B:$B,$B25)) | I25: =sum(C25+1.2*D25+1.5*E25+2*F25+2*G25)-H25 -> 0
A26: F/C | C26: =IF($B26="","",SUMIFS(Raw_Stats!$C:$C,Raw_Stats!$A:$A,">="&$B$1,Raw_Stats!$A:$A,"<="&$B$2,Raw_Stats!$B:$B,$B26)) | D26: =IF($B26="","",SUMIFS(Raw_Stats!$D:$D,Raw_Stats!$A:$A,">="&$B$1,Raw_Stats!$A:$A,"<="&$B$2,Raw_Stats!$B:$B,$B26)) | E26: =IF($B26="","",SUMIFS(Raw_Stats!$E:$E,Raw_Stats!$A:$A,">="&$B$1,Raw_Stats!$A:$A,"<="&$B$2,Raw_Stats!$B:$B,$B26)) | F26: =IF($B26="","",SUMIFS(Raw_Stats!$F:$F,Raw_Stats!$A:$A,">="&$B$1,Raw_Stats!$A:$A,"<="&$B$2,Raw_Stats!$B:$B,$B26)) | G26: =IF($B26="","",SUMIFS(Raw_Stats!$G:$G,Raw_Stats!$A:$A,">="&$B$1,Raw_Stats!$A:$A,"<="&$B$2,Raw_Stats!$B:$B,$B26)) | H26: =IF($B26="","",SUMIFS(Raw_Stats!$H:$H,Raw_Stats!$A:$A,">="&$B$1,Raw_Stats!$A:$A,"<="&$B$2,Raw_Stats!$B:$B,$B26)) | I26: =sum(C26+1.2*D26+1.5*E26+2*F26+2*G26)-H26 -> 0
A27: F/C | C27: =IF($B27="","",SUMIFS(Raw_Stats!$C:$C,Raw_Stats!$A:$A,">="&$B$1,Raw_Stats!$A:$A,"<="&$B$2,Raw_Stats!$B:$B,$B27)) | D27: =IF($B27="","",SUMIFS(Raw_Stats!$D:$D,Raw_Stats!$A:$A,">="&$B$1,Raw_Stats!$A:$A,"<="&$B$2,Raw_Stats!$B:$B,$B27)) | E27: =IF($B27="","",SUMIFS(Raw_Stats!$E:$E,Raw_Stats!$A:$A,">="&$B$1,Raw_Stats!$A:$A,"<="&$B$2,Raw_Stats!$B:$B,$B27)) | F27: =IF($B27="","",SUMIFS(Raw_Stats!$F:$F,Raw_Stats!$A:$A,">="&$B$1,Raw_Stats!$A:$A,"<="&$B$2,Raw_Stats!$B:$B,$B27)) | G27: =IF($B27="","",SUMIFS(Raw_Stats!$G:$G,Raw_Stats!$A:$A,">="&$B$1,Raw_Stats!$A:$A,"<="&$B$2,Raw_Stats!$B:$B,$B27)) | H27: =IF($B27="","",SUMIFS(Raw_Stats!$H:$H,Raw_Stats!$A:$A,">="&$B$1,Raw_Stats!$A:$A,"<="&$B$2,Raw_Stats!$B:$B,$B27)) | I27: =sum(C27+1.2*D27+1.5*E27+2*F27+2*G27)-H27 -> 0
A28: F/C | C28: =IF($B28="","",SUMIFS(Raw_Stats!$C:$C,Raw_Stats!$A:$A,">="&$B$1,Raw_Stats!$A:$A,"<="&$B$2,Raw_Stats!$B:$B,$B28)) | D28: =IF($B28="","",SUMIFS(Raw_Stats!$D:$D,Raw_Stats!$A:$A,">="&$B$1,Raw_Stats!$A:$A,"<="&$B$2,Raw_Stats!$B:$B,$B28)) | E28: =IF($B28="","",SUMIFS(Raw_Stats!$E:$E,Raw_Stats!$A:$A,">="&$B$1,Raw_Stats!$A:$A,"<="&$B$2,Raw_Stats!$B:$B,$B28)) | F28: =IF($B28="","",SUMIFS(Raw_Stats!$F:$F,Raw_Stats!$A:$A,">="&$B$1,Raw_Stats!$A:$A,"<="&$B$2,Raw_Stats!$B:$B,$B28)) | G28: =IF($B28="","",SUMIFS(Raw_Stats!$G:$G,Raw_Stats!$A:$A,">="&$B$1,Raw_Stats!$A:$A,"<="&$B$2,Raw_Stats!$B:$B,$B28)) | H28: =IF($B28="","",SUMIFS(Raw_Stats!$H:$H,Raw_Stats!$A:$A,">="&$B$1,Raw_Stats!$A:$A,"<="&$B$2,Raw_Stats!$B:$B,$B28)) | I28: =sum(C28+1.2*D28+1.5*E28+2*F28+2*G28)-H28 -> 0
B29: Totals | C29: =SUM(C24:C28) -> 0 | D29: =SUM(D24:D28)*1.2 -> 0 | E29: =SUM(E24:E28)*1.5 -> 0 | F29: =SUM(F24:F28)*2 -> 0 | G29: =SUM(G24:G28)*2 -> 0 | H29: =SUM(H24:H28) *-1 -> 0 | I29: =SUM(C29:H29) -> 0
A31: Josh | I31: =I38 -> 0
A32: Position | B32: Player | C32: Points (1) | D32: Rebounds (1.2) | E32: Assists (1.5) | F32: Steals (2) | G32: Blocks (2) | H32: Turnovers (-1) | I32: Total
A33: G | C33: =IF($B33="","",SUMIFS(Raw_Stats!$C:$C,Raw_Stats!$A:$A,">="&$B$1,Raw_Stats!$A:$A,"<="&$B$2,Raw_Stats!$B:$B,$B33)) | D33: =IF($B33="","",SUMIFS(Raw_Stats!$D:$D,Raw_Stats!$A:$A,">="&$B$1,Raw_Stats!$A:$A,"<="&$B$2,Raw_Stats!$B:$B,$B33)) | E33: =IF($B33="","",SUMIFS(Raw_Stats!$E:$E,Raw_Stats!$A:$A,">="&$B$1,Raw_Stats!$A:$A,"<="&$B$2,Raw_Stats!$B:$B,$B33)) | F33: =IF($B33="","",SUMIFS(Raw_Stats!$F:$F,Raw_Stats!$A:$A,">="&$B$1,Raw_Stats!$A:$A,"<="&$B$2,Raw_Stats!$B:$B,$B33)) | G33: =IF($B33="","",SUMIFS(Raw_Stats!$G:$G,Raw_Stats!$A:$A,">="&$B$1,Raw_Stats!$A:$A,"<="&$B$2,Raw_Stats!$B:$B,$B33)) | H33: =IF($B33="","",SUMIFS(Raw_Stats!$H:$H,Raw_Stats!$A:$A,">="&$B$1,Raw_Stats!$A:$A,"<="&$B$2,Raw_Stats!$B:$B,$B33)) | I33: =sum(C33+1.2*D33+1.5*E33+2*F33+2*G33)-H33 -> 0
A34: G | C34: =IF($B34="","",SUMIFS(Raw_Stats!$C:$C,Raw_Stats!$A:$A,">="&$B$1,Raw_Stats!$A:$A,"<="&$B$2,Raw_Stats!$B:$B,$B34)) | D34: =IF($B34="","",SUMIFS(Raw_Stats!$D:$D,Raw_Stats!$A:$A,">="&$B$1,Raw_Stats!$A:$A,"<="&$B$2,Raw_Stats!$B:$B,$B34)) | E34: =IF($B34="","",SUMIFS(Raw_Stats!$E:$E,Raw_Stats!$A:$A,">="&$B$1,Raw_Stats!$A:$A,"<="&$B$2,Raw_Stats!$B:$B,$B34)) | F34: =IF($B34="","",SUMIFS(Raw_Stats!$F:$F,Raw_Stats!$A:$A,">="&$B$1,Raw_Stats!$A:$A,"<="&$B$2,Raw_Stats!$B:$B,$B34)) | G34: =IF($B34="","",SUMIFS(Raw_Stats!$G:$G,Raw_Stats!$A:$A,">="&$B$1,Raw_Stats!$A:$A,"<="&$B$2,Raw_Stats!$B:$B,$B34)) | H34: =IF($B34="","",SUMIFS(Raw_Stats!$H:$H,Raw_Stats!$A:$A,">="&$B$1,Raw_Stats!$A:$A,"<="&$B$2,Raw_Stats!$B:$B,$B34)) | I34: =sum(C34+1.2*D34+1.5*E34+2*F34+2*G34)-H34 -> 0
A35: F/C | C35: =IF($B35="","",SUMIFS(Raw_Stats!$C:$C,Raw_Stats!$A:$A,">="&$B$1,Raw_Stats!$A:$A,"<="&$B$2,Raw_Stats!$B:$B,$B35)) | D35: =IF($B35="","",SUMIFS(Raw_Stats!$D:$D,Raw_Stats!$A:$A,">="&$B$1,Raw_Stats!$A:$A,"<="&$B$2,Raw_Stats!$B:$B,$B35)) | E35: =IF($B35="","",SUMIFS(Raw_Stats!$E:$E,Raw_Stats!$A:$A,">="&$B$1,Raw_Stats!$A:$A,"<="&$B$2,Raw_Stats!$B:$B,$B35)) | F35: =IF($B35="","",SUMIFS(Raw_Stats!$F:$F,Raw_Stats!$A:$A,">="&$B$1,Raw_Stats!$A:$A,"<="&$B$2,Raw_Stats!$B:$B,$B35)) | G35: =IF($B35="","",SUMIFS(Raw_Stats!$G:$G,Raw_Stats!$A:$A,">="&$B$1,Raw_Stats!$A:$A,"<="&$B$2,Raw_Stats!$B:$B,$B35)) | H35: =IF($B35="","",SUMIFS(Raw_Stats!$H:$H,Raw_Stats!$A:$A,">="&$B$1,Raw_Stats!$A:$A,"<="&$B$2,Raw_Stats!$B:$B,$B35)) | I35: =sum(C35+1.2*D35+1.5*E35+2*F35+2*G35)-H35 -> 0
A36: F/C | C36: =IF($B36="","",SUMIFS(Raw_Stats!$C:$C,Raw_Stats!$A:$A,">="&$B$1,Raw_Stats!$A:$A,"<="&$B$2,Raw_Stats!$B:$B,$B36)) | D36: =IF($B36="","",SUMIFS(Raw_Stats!$D:$D,Raw_Stats!$A:$A,">="&$B$1,Raw_Stats!$A:$A,"<="&$B$2,Raw_Stats!$B:$B,$B36)) | E36: =IF($B36="","",SUMIFS(Raw_Stats!$E:$E,Raw_Stats!$A:$A,">="&$B$1,Raw_Stats!$A:$A,"<="&$B$2,Raw_Stats!$B:$B,$B36)) | F36: =IF($B36="","",SUMIFS(Raw_Stats!$F:$F,Raw_Stats!$A:$A,">="&$B$1,Raw_Stats!$A:$A,"<="&$B$2,Raw_Stats!$B:$B,$B36)) | G36: =IF($B36="","",SUMIFS(Raw_Stats!$G:$G,Raw_Stats!$A:$A,">="&$B$1,Raw_Stats!$A:$A,"<="&$B$2,Raw_Stats!$B:$B,$B36)) | H36: =IF($B36="","",SUMIFS(Raw_Stats!$H:$H,Raw_Stats!$A:$A,">="&$B$1,Raw_Stats!$A:$A,"<="&$B$2,Raw_Stats!$B:$B,$B36)) | I36: =sum(C36+1.2*D36+1.5*E36+2*F36+2*G36)-H36 -> 0
A37: F/C | C37: =IF($B37="","",SUMIFS(Raw_Stats!$C:$C,Raw_Stats!$A:$A,">="&$B$1,Raw_Stats!$A:$A,"<="&$B$2,Raw_Stats!$B:$B,$B37)) | D37: =IF($B37="","",SUMIFS(Raw_Stats!$D:$D,Raw_Stats!$A:$A,">="&$B$1,Raw_Stats!$A:$A,"<="&$B$2,Raw_Stats!$B:$B,$B37)) | E37: =IF($B37="","",SUMIFS(Raw_Stats!$E:$E,Raw_Stats!$A:$A,">="&$B$1,Raw_Stats!$A:$A,"<="&$B$2,Raw_Stats!$B:$B,$B37)) | F37: =IF($B37="","",SUMIFS(Raw_Stats!$F:$F,Raw_Stats!$A:$A,">="&$B$1,Raw_Stats!$A:$A,"<="&$B$2,Raw_Stats!$B:$B,$B37)) | G37: =IF($B37="","",SUMIFS(Raw_Stats!$G:$G,Raw_Stats!$A:$A,">="&$B$1,Raw_Stats!$A:$A,"<="&$B$2,Raw_Stats!$B:$B,$B37)) | H37: =IF($B37="","",SUMIFS(Raw_Stats!$H:$H,Raw_Stats!$A:$A,">="&$B$1,Raw_Stats!$A:$A,"<="&$B$2,Raw_Stats!$B:$B,$B37)) | I37: =sum(C37+1.2*D37+1.5*E37+2*F37+2*G37)-H37 -> 0
B38: Totals | C38: =SUM(C33:C37) -> 0 | D38: =SUM(D33:D37)*1.2 -> 0 | E38: =SUM(E33:E37)*1.5 -> 0 | F38: =SUM(F33:F37)*2 -> 0 | G38: =SUM(G33:G37)*2 -> 0 | H38: =SUM(H33:H37) *-1 -> 0 | I38: =SUM(C38:H38) -> 0

Sheet 41926
A1: Start Date | B1: 46131 | C1: Update Stats | D1: FALSE | E1: Last Update | F1: 46131.988 | K1: Completed Games | M1: In Progress
A2: End Date | B2: 46131 | C2: Create Today Tab | D2: FALSE | E2: Status | F2: Stats updated (15 rows, 4 games, 15 active players) | K2: Andy | L2: 46147 | M2: 0/5
K3: Josh | L3: 46147 | M3: 0/5
A4: Andy | I4: =I11 -> 157.8 | K4: Jon | L4: 0/5 | M4: 0/5
A5: Position | B5: Player | C5: Points (1) | D5: Rebounds (1.2) | E5: Assists (1.5) | F5: Steals (2) | G5: Blocks (2) | H5: Turnovers (-1) | I5: Total | K5: Mark | L5: 46147 | M5: 0/5
A6: G | B6: Tyrese Maxey | C6: 21 | D6: 1 | E6: 8 | F6: 0 | G6: 0 | H6: 3 | I6: =sum(C6+1.2*D6+1.5*E6+2*F6+2*G6)-H6 -> 31.2 | J6: Final
A7: G | B7: Jalen Green | C7: 17 | D7: 5 | E7: 1 | F7: 1 | G7: 1 | H7: 3 | I7: =sum(C7+1.2*D7+1.5*E7+2*F7+2*G7)-H7 -> 25.5 | J7: Final
A8: F/C | B8: Victor Wembanyama | C8: 35 | D8: 5 | E8: 1 | F8: 0 | G8: 2 | H8: 4 | I8: =sum(C8+1.2*D8+1.5*E8+2*F8+2*G8)-H8 -> 42.5 | J8: Final
A9: F/C | B9: Jaylen Brown | C9: 26 | D9: 4 | E9: 3 | F9: 2 | G9: 0 | H9: 2 | I9: =sum(C9+1.2*D9+1.5*E9+2*F9+2*G9)-H9 -> 37.3 | J9: Final
A10: F/C | B10: Paul George | C10: 17 | D10: 4 | E10: 1 | F10: 0 | G10: 0 | H10: 2 | I10: =sum(C10+1.2*D10+1.5*E10+2*F10+2*G10)-H10 -> 21.3 | J10: Final
B11: Totals | C11: =SUM(C6:C10) -> 116 | D11: =SUM(D6:D10)*1.2 -> 22.8 | E11: =SUM(E6:E10)*1.5 -> 21 | F11: =SUM(F6:F10)*2 -> 6 | G11: =SUM(G6:G10)*2 -> 6 | H11: =SUM(H6:H10) *-1 -> -14 | I11: =SUM(C11:H11) -> 157.8
A13: Jon | I13: =I20 -> 0
A14: Position | B14: Player | C14: Points (1) | D14: Rebounds (1.2) | E14: Assists (1.5) | F14: Steals (2) | G14: Blocks (2) | H14: Turnovers (-1) | I14: Total
A15: G | I15: =sum(C15+1.2*D15+1.5*E15+2*F15+2*G15)-H15 -> 0
A16: G | I16: =sum(C16+1.2*D16+1.5*E16+2*F16+2*G16)-H16 -> 0
A17: F/C | I17: =sum(C17+1.2*D17+1.5*E17+2*F17+2*G17)-H17 -> 0
A18: F/C | I18: =sum(C18+1.2*D18+1.5*E18+2*F18+2*G18)-H18 -> 0
A19: F/C | I19: =sum(C19+1.2*D19+1.5*E19+2*F19+2*G19)-H19 -> 0
B20: Totals | C20: =SUM(C15:C19) -> 0 | D20: =SUM(D15:D19)*1.2 -> 0 | E20: =SUM(E15:E19)*1.5 -> 0 | F20: =SUM(F15:F19)*2 -> 0 | G20: =SUM(G15:G19)*2 -> 0 | H20: =SUM(H15:H19) *-1 -> 0 | I20: =SUM(C20:H20) -> 0
A22: Mark | I22: =I29 -> 213.8
A23: Position | B23: Player | C23: Points (1) | D23: Rebounds (1.2) | E23: Assists (1.5) | F23: Steals (2) | G23: Blocks (2) | H23: Turnovers (-1) | I23: Total
A24: G | B24: Cade Cunningham | C24: 39 | D24: 5 | E24: 4 | F24: 0 | G24: 0 | H24: 3 | I24: =sum(C24+1.2*D24+1.5*E24+2*F24+2*G24)-H24 -> 48 | J24: Final
A25: G | B25: Stephon Castle | C25: 17 | D25: 7 | E25: 7 | F25: 0 | G25: 0 | H25: 3 | I25: =sum(C25+1.2*D25+1.5*E25+2*F25+2*G25)-H25 -> 32.9 | J25: Final
A26: F/C | B26: Jayson Tatum | C26: 25 | D26: 11 | E26: 7 | F26: 2 | G26: 0 | H26: 1 | I26: =sum(C26+1.2*D26+1.5*E26+2*F26+2*G26)-H26 -> 51.7 | J26: Final
A27: F/C | B27: Paolo Banchero | C27: 23 | D27: 9 | E27: 4 | F27: 1 | G27: 0 | H27: 3 | I27: =sum(C27+1.2*D27+1.5*E27+2*F27+2*G27)-H27 -> 38.8 | J27: Final
A28: F/C | B28: Jalen Williams | C28: 22 | D28: 7 | E28: 6 | F28: 1 | G28: 1 | H28: 1 | I28: =sum(C28+1.2*D28+1.5*E28+2*F28+2*G28)-H28 -> 42.4 | J28: Final
B29: Totals | C29: =SUM(C24:C28) -> 126 | D29: =SUM(D24:D28)*1.2 -> 46.8 | E29: =SUM(E24:E28)*1.5 -> 42 | F29: =SUM(F24:F28)*2 -> 8 | G29: =SUM(G24:G28)*2 -> 2 | H29: =SUM(H24:H28) *-1 -> -11 | I29: =SUM(C29:H29) -> 213.8
A31: Josh | I31: =I38 -> 174.3
A32: Position | B32: Player | C32: Points (1) | D32: Rebounds (1.2) | E32: Assists (1.5) | F32: Steals (2) | G32: Blocks (2) | H32: Turnovers (-1) | I32: Total
A33: G | B33: Shai Gilgeous-Alexander | C33: 25 | D33: 4 | E33: 7 | F33: 0 | G33: 2 | H33: 0 | I33: =sum(C33+1.2*D33+1.5*E33+2*F33+2*G33)-H33 -> 44.3 | J33: Final
A34: G | B34: Devin Booker | C34: 23 | D34: 6 | E34: 2 | F34: 0 | G34: 0 | H34: 3 | I34: =sum(C34+1.2*D34+1.5*E34+2*F34+2*G34)-H34 -> 30.2 | J34: Final
A35: F/C | B35: Deni Avdija | C35: 30 | D35: 10 | E35: 5 | F35: 1 | G35: 1 | H35: 2 | I35: =sum(C35+1.2*D35+1.5*E35+2*F35+2*G35)-H35 -> 51.5 | J35: Final
A36: F/C | B36: Jalen Duren | C36: 8 | D36: 7 | E36: 1 | F36: 0 | G36: 1 | H36: 3 | I36: =sum(C36+1.2*D36+1.5*E36+2*F36+2*G36)-H36 -> 16.9 | J36: Final
A37: F/C | B37: Chet Holmgren | C37: 16 | D37: 7 | E37: 0 | F37: 2 | G37: 2 | H37: 1 | I37: =sum(C37+1.2*D37+1.5*E37+2*F37+2*G37)-H37 -> 31.4 | J37: Final
B38: Totals | C38: =SUM(C33:C37) -> 102 | D38: =SUM(D33:D37)*1.2 -> 40.8 | E38: =SUM(E33:E37)*1.5 -> 22.5 | F38: =SUM(F33:F37)*2 -> 6 | G38: =SUM(G33:G37)*2 -> 12 | H38: =SUM(H33:H37) *-1 -> -9 | I38: =SUM(C38:H38) -> 174.3

Sheet Raw_Stats
A1: Game Date | B1: Player | C1: PTS | D1: REB | E1: AST | F1: STL | G1: BLK | H1: TO | I1: Pulled At | J1: Event ID | K1: Status | L1: Canonical Player
A2: 46132 | B2: Brandon Ingram | C2: 7 | D2: 4 | E2: 3 | F2: 1 | G2: 0 | H2: 5 | I2: 46133.254 | J2: 401869369 | K2: Final | L2: brandon ingram
A3: 46132 | B3: Scottie Barnes | C3: 26 | D3: 4 | E3: 5 | F3: 2 | G3: 1 | H3: 4 | I3: 46133.254 | J3: 401869369 | K3: Final | L3: scottie barnes
A4: 46132 | B4: Evan Mobley | C4: 25 | D4: 8 | E4: 2 | F4: 0 | G4: 1 | H4: 1 | I4: 46133.254 | J4: 401869369 | K4: Final | L4: evan mobley
A5: 46132 | B5: James Harden | C5: 28 | D5: 5 | E5: 4 | F5: 5 | G5: 1 | H5: 5 | I5: 46133.254 | J5: 401869369 | K5: Final | L5: james harden
A6: 46132 | B6: Donovan Mitchell | C6: 30 | D6: 7 | E6: 5 | F6: 1 | G6: 0 | H6: 1 | I6: 46133.254 | J6: 401869369 | K6: Final | L6: donovan mitchell
A7: 46132 | B7: Jalen Johnson | C7: 17 | D7: 8 | E7: 3 | F7: 1 | G7: 0 | H7: 3 | I7: 46133.254 | J7: 401869387 | K7: Final | L7: jalen johnson
A8: 46132 | B8: Nickeil Alexander-Walker | C8: 9 | D8: 5 | E8: 6 | F8: 0 | G8: 3 | H8: 2 | I8: 46133.254 | J8: 401869387 | K8: Final | L8: nickeil alexander walker
A9: 46132 | B9: Karl-Anthony Towns | C9: 18 | D9: 8 | E9: 2 | F9: 0 | G9: 2 | H9: 3 | I9: 46133.254 | J9: 401869387 | K9: Final | L9: karl anthony towns
A10: 46132 | B10: Jalen Brunson | C10: 29 | D10: 2 | E10: 7 | F10: 0 | G10: 0 | H10: 3 | I10: 46133.254 | J10: 401869387 | K10: Final | L10: jalen brunson
A11: 46132 | B11: Julius Randle | C11: 24 | D11: 9 | E11: 6 | F11: 0 | G11: 0 | H11: 1 | I11: 46133.254 | J11: 401869395 | K11: Final | L11: julius randle
A12: 46132 | B12: Rudy Gobert | C12: 2 | D12: 7 | E12: 1 | F12: 2 | G12: 0 | H12: 2 | I12: 46133.254 | J12: 401869395 | K12: Final | L12: rudy gobert
A13: 46132 | B13: Anthony Edwards | C13: 30 | D13: 10 | E13: 2 | F13: 1 | G13: 2 | H13: 2 | I13: 46133.254 | J13: 401869395 | K13: Final | L13: anthony edwards
... A16: 46132 | B16: Jamal Murray | C16: 30 | D16: 7 | E16: 7 | F16: 1 | G16: 0 | H16: 4 | I16: 46133.254 | J16: 401869395 | K16: Final | L16: jamal murray

Sheet Name_Map
A1: Sheet_Name | B1: Source_Name
A2: Alperun Sengun | B2: Alperen Sengun
A3: Giannis Antetekoumpo | B3: Giannis Antetokounmpo

Sheet Player_Map
A1: Player | B1: Eligible_Position | D1: Guard_List | E1: Frontcourt_List
A2: =IFERROR(__xludf.DUMMYFUNCTION("QUERY({ 'NBA Player List'!K92:K250, ARRAYFORMULA(IF('NBA Player List'!K92:K250<>"""",""F/C"","""")); 'NBA Player List'!N92:N249, ARRAYFORMULA(IF('NBA Player List'!N92:N249<>"""",""G"","""")) }, ""select Col1, Col2 where Col1 is not null"", 0)"),"Giannis Antetekoumpo") -> Giannis Antetekoumpo | B2: =IFERROR(__xludf.DUMMYFUNCTION("""COMPUTED_VALUE"""),"F/C") -> F/C | D2: =IFERROR(__xludf.DUMMYFUNCTION("FILTER(A2:A1000,B2:B1000=""G"")"),"Anthony Edwards") -> Anthony Edwards | E2: =IFERROR(__xludf.DUMMYFUNCTION("FILTER(A2:A1000,B2:B1000=""F/C"")"),"Giannis Antetekoumpo") -> Giannis Antetekoumpo
A3: =IFERROR(__xludf.DUMMYFUNCTION("""COMPUTED_VALUE"""),"Nikola Jokic") -> Nikola Jokic | B3: =IFERROR(__xludf.DUMMYFUNCTION("""COMPUTED_VALUE"""),"F/C") -> F/C | D3: =IFERROR(__xludf.DUMMYFUNCTION("""COMPUTED_VALUE"""),"Cade Cunningham") -> Cade Cunningham | E3: =IFERROR(__xludf.DUMMYFUNCTION("""COMPUTED_VALUE"""),"Nikola Jokic") -> Nikola Jokic
A4: =IFERROR(__xludf.DUMMYFUNCTION("""COMPUTED_VALUE"""),"Jayson Tatum") -> Jayson Tatum | B4: =IFERROR(__xludf.DUMMYFUNCTION("""COMPUTED_VALUE"""),"F/C") -> F/C | D4: =IFERROR(__xludf.DUMMYFUNCTION("""COMPUTED_VALUE"""),"Luka Doncic") -> Luka Doncic | E4: =IFERROR(__xludf.DUMMYFUNCTION("""COMPUTED_VALUE"""),"Jayson Tatum") -> Jayson Tatum
A5: =IFERROR(__xludf.DUMMYFUNCTION("""COMPUTED_VALUE"""),"LeBron James") -> LeBron James | B5: =IFERROR(__xludf.DUMMYFUNCTION("""COMPUTED_VALUE"""),"F/C") -> F/C | D5: =IFERROR(__xludf.DUMMYFUNCTION("""COMPUTED_VALUE"""),"Jalen Brunson") -> Jalen Brunson | E5: =IFERROR(__xludf.DUMMYFUNCTION("""COMPUTED_VALUE"""),"LeBron James") -> LeBron James
A6: =IFERROR(__xludf.DUMMYFUNCTION("""COMPUTED_VALUE"""),"Paolo Banchero") -> Paolo Banchero | B6: =IFERROR(__xludf.DUMMYFUNCTION("""COMPUTED_VALUE"""),"F/C") -> F/C | D6: =IFERROR(__xludf.DUMMYFUNCTION("""COMPUTED_VALUE"""),"Shai Gilgeous-Alexander") -> Shai Gilgeous-Alexander | E6: =IFERROR(__xludf.DUMMYFUNCTION("""COMPUTED_VALUE"""),"Paolo Banchero") -> Paolo Banchero
A7: =IFERROR(__xludf.DUMMYFUNCTION("""COMPUTED_VALUE"""),"Alperun Sengun") -> Alperun Sengun | B7: =IFERROR(__xludf.DUMMYFUNCTION("""COMPUTED_VALUE"""),"F/C") -> F/C | D7: =IFERROR(__xludf.DUMMYFUNCTION("""COMPUTED_VALUE"""),"Tyrese Haliburton") -> Tyrese Haliburton | E7: =IFERROR(__xludf.DUMMYFUNCTION("""COMPUTED_VALUE"""),"Alperun Sengun") -> Alperun Sengun
A8: =IFERROR(__xludf.DUMMYFUNCTION("""COMPUTED_VALUE"""),"Kawhi Leonard") -> Kawhi Leonard | B8: =IFERROR(__xludf.DUMMYFUNCTION("""COMPUTED_VALUE"""),"F/C") -> F/C | D8: =IFERROR(__xludf.DUMMYFUNCTION("""COMPUTED_VALUE"""),"Brandin Podziemski") -> Brandin Podziemski | E8: =IFERROR(__xludf.DUMMYFUNCTION("""COMPUTED_VALUE"""),"Kawhi Leonard") -> Kawhi Leonard
A9: =IFERROR(__xludf.DUMMYFUNCTION("""COMPUTED_VALUE"""),"Franz Wagner") -> Franz Wagner | B9: =IFERROR(__xludf.DUMMYFUNCTION("""COMPUTED_VALUE"""),"F/C") -> F/C | D9: =IFERROR(__xludf.DUMMYFUNCTION("""COMPUTED_VALUE"""),"Jamal Murray") -> Jamal Murray | E9: =IFERROR(__xludf.DUMMYFUNCTION("""COMPUTED_VALUE"""),"Franz Wagner") -> Franz Wagner
A10: =IFERROR(__xludf.DUMMYFUNCTION("""COMPUTED_VALUE"""),"Jalen Williams") -> Jalen Williams | B10: =IFERROR(__xludf.DUMMYFUNCTION("""COMPUTED_VALUE"""),"F/C") -> F/C | D10: =IFERROR(__xludf.DUMMYFUNCTION("""COMPUTED_VALUE"""),"James Harden") -> James Harden | E10: =IFERROR(__xludf.DUMMYFUNCTION("""COMPUTED_VALUE"""),"Jalen Williams") -> Jalen Williams
A11: =IFERROR(__xludf.DUMMYFUNCTION("""COMPUTED_VALUE"""),"Karl-Anthony Towns") -> Karl-Anthony Towns | B11: =IFERROR(__xludf.DUMMYFUNCTION("""COMPUTED_VALUE"""),"F/C") -> F/C | D11: =IFERROR(__xludf.DUMMYFUNCTION("""COMPUTED_VALUE"""),"Stephen Curry") -> Stephen Curry | E11: =IFERROR(__xludf.DUMMYFUNCTION("""COMPUTED_VALUE"""),"Karl-Anthony Towns") -> Karl-Anthony Towns
A12: =IFERROR(__xludf.DUMMYFUNCTION("""COMPUTED_VALUE"""),"Rudy Gobert") -> Rudy Gobert | B12: =IFERROR(__xludf.DUMMYFUNCTION("""COMPUTED_VALUE"""),"F/C") -> F/C | D12: =IFERROR(__xludf.DUMMYFUNCTION("""COMPUTED_VALUE"""),"Darius Garland") -> Darius Garland | E12: =IFERROR(__xludf.DUMMYFUNCTION("""COMPUTED_VALUE"""),"Rudy Gobert") -> Rudy Gobert
A13: =IFERROR(__xludf.DUMMYFUNCTION("""COMPUTED_VALUE"""),"Ivica Zubac") -> Ivica Zubac | B13: =IFERROR(__xludf.DUMMYFUNCTION("""COMPUTED_VALUE"""),"F/C") -> F/C | D13: =IFERROR(__xludf.DUMMYFUNCTION("""COMPUTED_VALUE"""),"Donovan Mitchell") -> Donovan Mitchell | E13: =IFERROR(__xludf.DUMMYFUNCTION("""COMPUTED_VALUE"""),"Ivica Zubac") -> Ivica Zubac
A14: =IFERROR(__xludf.DUMMYFUNCTION("""COMPUTED_VALUE"""),"Bam Adebayo") -> Bam Adebayo | B14: =IFERROR(__xludf.DUMMYFUNCTION("""COMPUTED_VALUE"""),"F/C") -> F/C | D14: =IFERROR(__xludf.DUMMYFUNCTION("""COMPUTED_VALUE"""),"Christian Braun") -> Christian Braun | E14: =IFERROR(__xludf.DUMMYFUNCTION("""COMPUTED_VALUE"""),"Bam Adebayo") -> Bam Adebayo
A15: =IFERROR(__xludf.DUMMYFUNCTION("""COMPUTED_VALUE"""),"Josh Hart") -> Josh Hart | B15: =IFERROR(__xludf.DUMMYFUNCTION("""COMPUTED_VALUE"""),"F/C") -> F/C | D15: =IFERROR(__xludf.DUMMYFUNCTION("""COMPUTED_VALUE"""),"Fred VanVleet") -> Fred VanVleet | E15: =IFERROR(__xludf.DUMMYFUNCTION("""COMPUTED_VALUE"""),"Josh Hart") -> Josh Hart
A16: =IFERROR(__xludf.DUMMYFUNCTION("""COMPUTED_VALUE"""),"Jaylen Brown") -> Jaylen Brown | B16: =IFERROR(__xludf.DUMMYFUNCTION("""COMPUTED_VALUE"""),"F/C") -> F/C | D16: =IFERROR(__xludf.DUMMYFUNCTION("""COMPUTED_VALUE"""),"Derrick White") -> Derrick White | E16: =IFERROR(__xludf.DUMMYFUNCTION("""COMPUTED_VALUE"""),"Jaylen Brown") -> Jaylen Brown
A17: =IFERROR(__xludf.DUMMYFUNCTION("""COMPUTED_VALUE"""),"Chet Holmgren") -> Chet Holmgren | B17: =IFERROR(__xludf.DUMMYFUNCTION("""COMPUTED_VALUE"""),"F/C") -> F/C | D17: =IFERROR(__xludf.DUMMYFUNCTION("""COMPUTED_VALUE"""),"Mikal Bridges") -> Mikal Bridges | E17: =IFERROR(__xludf.DUMMYFUNCTION("""COMPUTED_VALUE"""),"Chet Holmgren") -> Chet Holmgren
A18: =IFERROR(__xludf.DUMMYFUNCTION("""COMPUTED_VALUE"""),"Julius Randle") -> Julius Randle | B18: =IFERROR(__xludf.DUMMYFUNCTION("""COMPUTED_VALUE"""),"F/C") -> F/C | D18: =IFERROR(__xludf.DUMMYFUNCTION("""COMPUTED_VALUE"""),"Ja Morant") -> Ja Morant | E18: =IFERROR(__xludf.DUMMYFUNCTION("""COMPUTED_VALUE"""),"Julius Randle") -> Julius Randle
A19: =IFERROR(__xludf.DUMMYFUNCTION("""COMPUTED_VALUE"""),"Michael Porter Jr.") -> Michael Porter Jr. | B19: =IFERROR(__xludf.DUMMYFUNCTION("""COMPUTED_VALUE"""),"F/C") -> F/C | D19: =IFERROR(__xludf.DUMMYFUNCTION("""COMPUTED_VALUE"""),"Jalen Green") -> Jalen Green | E19: =IFERROR(__xludf.DUMMYFUNCTION("""COMPUTED_VALUE"""),"Michael Porter Jr.") -> Michael Porter Jr.
A20: =IFERROR(__xludf.DUMMYFUNCTION("""COMPUTED_VALUE"""),"Jarrett Allen") -> Jarrett Allen | B20: =IFERROR(__xludf.DUMMYFUNCTION("""COMPUTED_VALUE"""),"F/C") -> F/C | D20: =IFERROR(__xludf.DUMMYFUNCTION("""COMPUTED_VALUE"""),"Tyler Herro") -> Tyler Herro | E20: =IFERROR(__xludf.DUMMYFUNCTION("""COMPUTED_VALUE"""),"Jarrett Allen") -> Jarrett Allen
A21: =IFERROR(__xludf.DUMMYFUNCTION("""COMPUTED_VALUE"""),"Jalen Duren") -> Jalen Duren | B21: =IFERROR(__xludf.DUMMYFUNCTION("""COMPUTED_VALUE"""),"F/C") -> F/C | D21: =IFERROR(__xludf.DUMMYFUNCTION("""COMPUTED_VALUE"""),"Austin Reaves") -> Austin Reaves | E21: =IFERROR(__xludf.DUMMYFUNCTION("""COMPUTED_VALUE"""),"Jalen Duren") -> Jalen Duren
A22: =IFERROR(__xludf.DUMMYFUNCTION("""COMPUTED_VALUE"""),"Pascal Siakam") -> Pascal Siakam | B22: =IFERROR(__xludf.DUMMYFUNCTION("""COMPUTED_VALUE"""),"F/C") -> F/C | D22: =IFERROR(__xludf.DUMMYFUNCTION("""COMPUTED_VALUE"""),"Donte DiVincenzo ") -> Donte DiVincenzo | E22: =IFERROR(__xludf.DUMMYFUNCTION("""COMPUTED_VALUE"""),"Pascal Siakam") -> Pascal Siakam
A23: =IFERROR(__xludf.DUMMYFUNCTION("""COMPUTED_VALUE"""),"Amen Thompson") -> Amen Thompson | B23: =IFERROR(__xludf.DUMMYFUNCTION("""COMPUTED_VALUE"""),"F/C") -> F/C | D23: =IFERROR(__xludf.DUMMYFUNCTION("""COMPUTED_VALUE"""),"Ty Jerome") -> Ty Jerome | E23: =IFERROR(__xludf.DUMMYFUNCTION("""COMPUTED_VALUE"""),"Amen Thompson") -> Amen Thompson
A24: =IFERROR(__xludf.DUMMYFUNCTION("""COMPUTED_VALUE"""),"Jimmy Butler") -> Jimmy Butler | B24: =IFERROR(__xludf.DUMMYFUNCTION("""COMPUTED_VALUE"""),"F/C") -> F/C | D24: =IFERROR(__xludf.DUMMYFUNCTION("""COMPUTED_VALUE"""),"Russell Westbrook") -> Russell Westbrook | E24: =IFERROR(__xludf.DUMMYFUNCTION("""COMPUTED_VALUE"""),"Jimmy Butler") -> Jimmy Butler
A25: =IFERROR(__xludf.DUMMYFUNCTION("""COMPUTED_VALUE"""),"Jaren Jackson Jr.") -> Jaren Jackson Jr. | B25: =IFERROR(__xludf.DUMMYFUNCTION("""COMPUTED_VALUE"""),"F/C") -> F/C | D25: =IFERROR(__xludf.DUMMYFUNCTION("""COMPUTED_VALUE"""),"Damian Lillard") -> Damian Lillard | E25: =IFERROR(__xludf.DUMMYFUNCTION("""COMPUTED_VALUE"""),"Jaren Jackson Jr.") -> Jaren Jackson Jr.
A26: =IFERROR(__xludf.DUMMYFUNCTION("""COMPUTED_VALUE"""),"Rui Hachimura") -> Rui Hachimura | B26: =IFERROR(__xludf.DUMMYFUNCTION("""COMPUTED_VALUE"""),"F/C") -> F/C | D26: =IFERROR(__xludf.DUMMYFUNCTION("""COMPUTED_VALUE"""),"Andrew Nembhard") -> Andrew Nembhard | E26: =IFERROR(__xludf.DUMMYFUNCTION("""COMPUTED_VALUE"""),"Rui Hachimura") -> Rui Hachimura
A27: =IFERROR(__xludf.DUMMYFUNCTION("""COMPUTED_VALUE"""),"Myles Turner") -> Myles Turner | B27: =IFERROR(__xludf.DUMMYFUNCTION("""COMPUTED_VALUE"""),"F/C") -> F/C | D27: =IFERROR(__xludf.DUMMYFUNCTION("""COMPUTED_VALUE"""),"Malik Beasley") -> Malik Beasley | E27: =IFERROR(__xludf.DUMMYFUNCTION("""COMPUTED_VALUE"""),"Myles Turner") -> Myles Turner
